2025-06-25 08:10:40,484 [ERROR] telegram: Failed to send Telegram message: HTTPSConnectionPool(host='api.telegram.org', port=443): Max retries exceeded with url: /bot7325593988:AAGEeA3L01rmfHqFZ38cF070G1WOTkv-8JU/sendMessage?chat_id=6468675993&text=Heartbeat%3A+2025-06-25+08%3A10%3A40&parse_mode=HTML (Caused by NewConnectionError('<urllib3.connection.HTTPSConnection object at 0x105c5aa50>: Failed to establish a new connection: [Errno 8] nodename nor servname provided, or not known'))
2025-06-25 08:10:40,490 [ERROR] true_data_utils: Attempt 1 fetch failed: HTTPSConnectionPool(host='auth.truedata.in', port=443): Max retries exceeded with url: /token (Caused by NewConnectionError('<urllib3.connection.HTTPSConnection object at 0x105c32e90>: Failed to establish a new connection: [Errno 8] nodename nor servname provided, or not known'))
Traceback (most recent call last):
  File "/Library/Frameworks/Python.framework/Versions/3.13/lib/python3.13/site-packages/urllib3/connection.py", line 174, in _new_conn
    conn = connection.create_connection(
        (self._dns_host, self.port), self.timeout, **extra_kw
    )
  File "/Library/Frameworks/Python.framework/Versions/3.13/lib/python3.13/site-packages/urllib3/util/connection.py", line 72, in create_connection
    for res in socket.getaddrinfo(host, port, family, socket.SOCK_STREAM):
               ~~~~~~~~~~~~~~~~~~^^^^^^^^^^^^^^^^^^^^^^^^^^^^^^^^^^^^^^^^
  File "/Library/Frameworks/Python.framework/Versions/3.13/lib/python3.13/socket.py", line 975, in getaddrinfo
    for res in _socket.getaddrinfo(host, port, family, type, proto, flags):
               ~~~~~~~~~~~~~~~~~~~^^^^^^^^^^^^^^^^^^^^^^^^^^^^^^^^^^^^^^^^
socket.gaierror: [Errno 8] nodename nor servname provided, or not known

During handling of the above exception, another exception occurred:

Traceback (most recent call last):
  File "/Library/Frameworks/Python.framework/Versions/3.13/lib/python3.13/site-packages/urllib3/connectionpool.py", line 716, in urlopen
    httplib_response = self._make_request(
        conn,
    ...<5 lines>...
        chunked=chunked,
    )
  File "/Library/Frameworks/Python.framework/Versions/3.13/lib/python3.13/site-packages/urllib3/connectionpool.py", line 404, in _make_request
    self._validate_conn(conn)
    ~~~~~~~~~~~~~~~~~~~^^^^^^
  File "/Library/Frameworks/Python.framework/Versions/3.13/lib/python3.13/site-packages/urllib3/connectionpool.py", line 1061, in _validate_conn
    conn.connect()
    ~~~~~~~~~~~~^^
  File "/Library/Frameworks/Python.framework/Versions/3.13/lib/python3.13/site-packages/urllib3/connection.py", line 363, in connect
    self.sock = conn = self._new_conn()
                       ~~~~~~~~~~~~~~^^
  File "/Library/Frameworks/Python.framework/Versions/3.13/lib/python3.13/site-packages/urllib3/connection.py", line 186, in _new_conn
    raise NewConnectionError(
        self, "Failed to establish a new connection: %s" % e
    )
urllib3.exceptions.NewConnectionError: <urllib3.connection.HTTPSConnection object at 0x105c32e90>: Failed to establish a new connection: [Errno 8] nodename nor servname provided, or not known

During handling of the above exception, another exception occurred:

Traceback (most recent call last):
  File "/Library/Frameworks/Python.framework/Versions/3.13/lib/python3.13/site-packages/requests/adapters.py", line 439, in send
    resp = conn.urlopen(
        method=request.method,
    ...<8 lines>...
        timeout=timeout
    )
  File "/Library/Frameworks/Python.framework/Versions/3.13/lib/python3.13/site-packages/urllib3/connectionpool.py", line 802, in urlopen
    retries = retries.increment(
        method, url, error=e, _pool=self, _stacktrace=sys.exc_info()[2]
    )
  File "/Library/Frameworks/Python.framework/Versions/3.13/lib/python3.13/site-packages/urllib3/util/retry.py", line 594, in increment
    raise MaxRetryError(_pool, url, error or ResponseError(cause))
urllib3.exceptions.MaxRetryError: HTTPSConnectionPool(host='auth.truedata.in', port=443): Max retries exceeded with url: /token (Caused by NewConnectionError('<urllib3.connection.HTTPSConnection object at 0x105c32e90>: Failed to establish a new connection: [Errno 8] nodename nor servname provided, or not known'))

During handling of the above exception, another exception occurred:

Traceback (most recent call last):
  File "/Users/aneeshviswanathan/Desktop/Updated_om_babaji_om /true_data_utils.py", line 44, in fetch_latest_ohlcv
    token = get_token()
  File "/Users/aneeshviswanathan/Desktop/Updated_om_babaji_om /true_data_utils.py", line 29, in get_token
    resp = requests.post(url, data=payload)
  File "/Library/Frameworks/Python.framework/Versions/3.13/lib/python3.13/site-packages/requests/api.py", line 119, in post
    return request('post', url, data=data, json=json, **kwargs)
  File "/Library/Frameworks/Python.framework/Versions/3.13/lib/python3.13/site-packages/requests/api.py", line 61, in request
    return session.request(method=method, url=url, **kwargs)
           ~~~~~~~~~~~~~~~^^^^^^^^^^^^^^^^^^^^^^^^^^^^^^^^^^
  File "/Library/Frameworks/Python.framework/Versions/3.13/lib/python3.13/site-packages/requests/sessions.py", line 542, in request
    resp = self.send(prep, **send_kwargs)
  File "/Library/Frameworks/Python.framework/Versions/3.13/lib/python3.13/site-packages/requests/sessions.py", line 655, in send
    r = adapter.send(request, **kwargs)
  File "/Library/Frameworks/Python.framework/Versions/3.13/lib/python3.13/site-packages/requests/adapters.py", line 516, in send
    raise ConnectionError(e, request=request)
requests.exceptions.ConnectionError: HTTPSConnectionPool(host='auth.truedata.in', port=443): Max retries exceeded with url: /token (Caused by NewConnectionError('<urllib3.connection.HTTPSConnection object at 0x105c32e90>: Failed to establish a new connection: [Errno 8] nodename nor servname provided, or not known'))
2025-06-25 08:10:45,503 [ERROR] true_data_utils: Attempt 2 fetch failed: HTTPSConnectionPool(host='auth.truedata.in', port=443): Max retries exceeded with url: /token (Caused by NewConnectionError('<urllib3.connection.HTTPSConnection object at 0x105c339d0>: Failed to establish a new connection: [Errno 8] nodename nor servname provided, or not known'))
Traceback (most recent call last):
  File "/Library/Frameworks/Python.framework/Versions/3.13/lib/python3.13/site-packages/urllib3/connection.py", line 174, in _new_conn
    conn = connection.create_connection(
        (self._dns_host, self.port), self.timeout, **extra_kw
    )
  File "/Library/Frameworks/Python.framework/Versions/3.13/lib/python3.13/site-packages/urllib3/util/connection.py", line 72, in create_connection
    for res in socket.getaddrinfo(host, port, family, socket.SOCK_STREAM):
               ~~~~~~~~~~~~~~~~~~^^^^^^^^^^^^^^^^^^^^^^^^^^^^^^^^^^^^^^^^
  File "/Library/Frameworks/Python.framework/Versions/3.13/lib/python3.13/socket.py", line 975, in getaddrinfo
    for res in _socket.getaddrinfo(host, port, family, type, proto, flags):
               ~~~~~~~~~~~~~~~~~~~^^^^^^^^^^^^^^^^^^^^^^^^^^^^^^^^^^^^^^^^
socket.gaierror: [Errno 8] nodename nor servname provided, or not known

During handling of the above exception, another exception occurred:

Traceback (most recent call last):
  File "/Library/Frameworks/Python.framework/Versions/3.13/lib/python3.13/site-packages/urllib3/connectionpool.py", line 716, in urlopen
    httplib_response = self._make_request(
        conn,
    ...<5 lines>...
        chunked=chunked,
    )
  File "/Library/Frameworks/Python.framework/Versions/3.13/lib/python3.13/site-packages/urllib3/connectionpool.py", line 404, in _make_request
    self._validate_conn(conn)
    ~~~~~~~~~~~~~~~~~~~^^^^^^
  File "/Library/Frameworks/Python.framework/Versions/3.13/lib/python3.13/site-packages/urllib3/connectionpool.py", line 1061, in _validate_conn
    conn.connect()
    ~~~~~~~~~~~~^^
  File "/Library/Frameworks/Python.framework/Versions/3.13/lib/python3.13/site-packages/urllib3/connection.py", line 363, in connect
    self.sock = conn = self._new_conn()
                       ~~~~~~~~~~~~~~^^
  File "/Library/Frameworks/Python.framework/Versions/3.13/lib/python3.13/site-packages/urllib3/connection.py", line 186, in _new_conn
    raise NewConnectionError(
        self, "Failed to establish a new connection: %s" % e
    )
urllib3.exceptions.NewConnectionError: <urllib3.connection.HTTPSConnection object at 0x105c339d0>: Failed to establish a new connection: [Errno 8] nodename nor servname provided, or not known

During handling of the above exception, another exception occurred:

Traceback (most recent call last):
  File "/Library/Frameworks/Python.framework/Versions/3.13/lib/python3.13/site-packages/requests/adapters.py", line 439, in send
    resp = conn.urlopen(
        method=request.method,
    ...<8 lines>...
        timeout=timeout
    )
  File "/Library/Frameworks/Python.framework/Versions/3.13/lib/python3.13/site-packages/urllib3/connectionpool.py", line 802, in urlopen
    retries = retries.increment(
        method, url, error=e, _pool=self, _stacktrace=sys.exc_info()[2]
    )
  File "/Library/Frameworks/Python.framework/Versions/3.13/lib/python3.13/site-packages/urllib3/util/retry.py", line 594, in increment
    raise MaxRetryError(_pool, url, error or ResponseError(cause))
urllib3.exceptions.MaxRetryError: HTTPSConnectionPool(host='auth.truedata.in', port=443): Max retries exceeded with url: /token (Caused by NewConnectionError('<urllib3.connection.HTTPSConnection object at 0x105c339d0>: Failed to establish a new connection: [Errno 8] nodename nor servname provided, or not known'))

During handling of the above exception, another exception occurred:

Traceback (most recent call last):
  File "/Users/aneeshviswanathan/Desktop/Updated_om_babaji_om /true_data_utils.py", line 44, in fetch_latest_ohlcv
    token = get_token()
  File "/Users/aneeshviswanathan/Desktop/Updated_om_babaji_om /true_data_utils.py", line 29, in get_token
    resp = requests.post(url, data=payload)
  File "/Library/Frameworks/Python.framework/Versions/3.13/lib/python3.13/site-packages/requests/api.py", line 119, in post
    return request('post', url, data=data, json=json, **kwargs)
  File "/Library/Frameworks/Python.framework/Versions/3.13/lib/python3.13/site-packages/requests/api.py", line 61, in request
    return session.request(method=method, url=url, **kwargs)
           ~~~~~~~~~~~~~~~^^^^^^^^^^^^^^^^^^^^^^^^^^^^^^^^^^
  File "/Library/Frameworks/Python.framework/Versions/3.13/lib/python3.13/site-packages/requests/sessions.py", line 542, in request
    resp = self.send(prep, **send_kwargs)
  File "/Library/Frameworks/Python.framework/Versions/3.13/lib/python3.13/site-packages/requests/sessions.py", line 655, in send
    r = adapter.send(request, **kwargs)
  File "/Library/Frameworks/Python.framework/Versions/3.13/lib/python3.13/site-packages/requests/adapters.py", line 516, in send
    raise ConnectionError(e, request=request)
requests.exceptions.ConnectionError: HTTPSConnectionPool(host='auth.truedata.in', port=443): Max retries exceeded with url: /token (Caused by NewConnectionError('<urllib3.connection.HTTPSConnection object at 0x105c339d0>: Failed to establish a new connection: [Errno 8] nodename nor servname provided, or not known'))
2025-06-25 08:10:50,519 [ERROR] true_data_utils: Attempt 3 fetch failed: HTTPSConnectionPool(host='auth.truedata.in', port=443): Max retries exceeded with url: /token (Caused by NewConnectionError('<urllib3.connection.HTTPSConnection object at 0x105c32e90>: Failed to establish a new connection: [Errno 8] nodename nor servname provided, or not known'))
Traceback (most recent call last):
  File "/Library/Frameworks/Python.framework/Versions/3.13/lib/python3.13/site-packages/urllib3/connection.py", line 174, in _new_conn
    conn = connection.create_connection(
        (self._dns_host, self.port), self.timeout, **extra_kw
    )
  File "/Library/Frameworks/Python.framework/Versions/3.13/lib/python3.13/site-packages/urllib3/util/connection.py", line 72, in create_connection
    for res in socket.getaddrinfo(host, port, family, socket.SOCK_STREAM):
               ~~~~~~~~~~~~~~~~~~^^^^^^^^^^^^^^^^^^^^^^^^^^^^^^^^^^^^^^^^
  File "/Library/Frameworks/Python.framework/Versions/3.13/lib/python3.13/socket.py", line 975, in getaddrinfo
    for res in _socket.getaddrinfo(host, port, family, type, proto, flags):
               ~~~~~~~~~~~~~~~~~~~^^^^^^^^^^^^^^^^^^^^^^^^^^^^^^^^^^^^^^^^
socket.gaierror: [Errno 8] nodename nor servname provided, or not known

During handling of the above exception, another exception occurred:

Traceback (most recent call last):
  File "/Library/Frameworks/Python.framework/Versions/3.13/lib/python3.13/site-packages/urllib3/connectionpool.py", line 716, in urlopen
    httplib_response = self._make_request(
        conn,
    ...<5 lines>...
        chunked=chunked,
    )
  File "/Library/Frameworks/Python.framework/Versions/3.13/lib/python3.13/site-packages/urllib3/connectionpool.py", line 404, in _make_request
    self._validate_conn(conn)
    ~~~~~~~~~~~~~~~~~~~^^^^^^
  File "/Library/Frameworks/Python.framework/Versions/3.13/lib/python3.13/site-packages/urllib3/connectionpool.py", line 1061, in _validate_conn
    conn.connect()
    ~~~~~~~~~~~~^^
  File "/Library/Frameworks/Python.framework/Versions/3.13/lib/python3.13/site-packages/urllib3/connection.py", line 363, in connect
    self.sock = conn = self._new_conn()
                       ~~~~~~~~~~~~~~^^
  File "/Library/Frameworks/Python.framework/Versions/3.13/lib/python3.13/site-packages/urllib3/connection.py", line 186, in _new_conn
    raise NewConnectionError(
        self, "Failed to establish a new connection: %s" % e
    )
urllib3.exceptions.NewConnectionError: <urllib3.connection.HTTPSConnection object at 0x105c32e90>: Failed to establish a new connection: [Errno 8] nodename nor servname provided, or not known

During handling of the above exception, another exception occurred:

Traceback (most recent call last):
  File "/Library/Frameworks/Python.framework/Versions/3.13/lib/python3.13/site-packages/requests/adapters.py", line 439, in send
    resp = conn.urlopen(
        method=request.method,
    ...<8 lines>...
        timeout=timeout
    )
  File "/Library/Frameworks/Python.framework/Versions/3.13/lib/python3.13/site-packages/urllib3/connectionpool.py", line 802, in urlopen
    retries = retries.increment(
        method, url, error=e, _pool=self, _stacktrace=sys.exc_info()[2]
    )
  File "/Library/Frameworks/Python.framework/Versions/3.13/lib/python3.13/site-packages/urllib3/util/retry.py", line 594, in increment
    raise MaxRetryError(_pool, url, error or ResponseError(cause))
urllib3.exceptions.MaxRetryError: HTTPSConnectionPool(host='auth.truedata.in', port=443): Max retries exceeded with url: /token (Caused by NewConnectionError('<urllib3.connection.HTTPSConnection object at 0x105c32e90>: Failed to establish a new connection: [Errno 8] nodename nor servname provided, or not known'))

During handling of the above exception, another exception occurred:

Traceback (most recent call last):
  File "/Users/aneeshviswanathan/Desktop/Updated_om_babaji_om /true_data_utils.py", line 44, in fetch_latest_ohlcv
    token = get_token()
  File "/Users/aneeshviswanathan/Desktop/Updated_om_babaji_om /true_data_utils.py", line 29, in get_token
    resp = requests.post(url, data=payload)
  File "/Library/Frameworks/Python.framework/Versions/3.13/lib/python3.13/site-packages/requests/api.py", line 119, in post
    return request('post', url, data=data, json=json, **kwargs)
  File "/Library/Frameworks/Python.framework/Versions/3.13/lib/python3.13/site-packages/requests/api.py", line 61, in request
    return session.request(method=method, url=url, **kwargs)
           ~~~~~~~~~~~~~~~^^^^^^^^^^^^^^^^^^^^^^^^^^^^^^^^^^
  File "/Library/Frameworks/Python.framework/Versions/3.13/lib/python3.13/site-packages/requests/sessions.py", line 542, in request
    resp = self.send(prep, **send_kwargs)
  File "/Library/Frameworks/Python.framework/Versions/3.13/lib/python3.13/site-packages/requests/sessions.py", line 655, in send
    r = adapter.send(request, **kwargs)
  File "/Library/Frameworks/Python.framework/Versions/3.13/lib/python3.13/site-packages/requests/adapters.py", line 516, in send
    raise ConnectionError(e, request=request)
requests.exceptions.ConnectionError: HTTPSConnectionPool(host='auth.truedata.in', port=443): Max retries exceeded with url: /token (Caused by NewConnectionError('<urllib3.connection.HTTPSConnection object at 0x105c32e90>: Failed to establish a new connection: [Errno 8] nodename nor servname provided, or not known'))
2025-06-25 08:10:50,525 [ERROR] true_data_utils: All TrueData fetch attempts failed
2025-06-25 08:11:00,714 [ERROR] true_data_utils: Attempt 1 fetch failed: HTTPSConnectionPool(host='auth.truedata.in', port=443): Max retries exceeded with url: /token (Caused by NewConnectionError('<urllib3.connection.HTTPSConnection object at 0x105c33c50>: Failed to establish a new connection: [Errno 8] nodename nor servname provided, or not known'))
Traceback (most recent call last):
  File "/Library/Frameworks/Python.framework/Versions/3.13/lib/python3.13/site-packages/urllib3/connection.py", line 174, in _new_conn
    conn = connection.create_connection(
        (self._dns_host, self.port), self.timeout, **extra_kw
    )
  File "/Library/Frameworks/Python.framework/Versions/3.13/lib/python3.13/site-packages/urllib3/util/connection.py", line 72, in create_connection
    for res in socket.getaddrinfo(host, port, family, socket.SOCK_STREAM):
               ~~~~~~~~~~~~~~~~~~^^^^^^^^^^^^^^^^^^^^^^^^^^^^^^^^^^^^^^^^
  File "/Library/Frameworks/Python.framework/Versions/3.13/lib/python3.13/socket.py", line 975, in getaddrinfo
    for res in _socket.getaddrinfo(host, port, family, type, proto, flags):
               ~~~~~~~~~~~~~~~~~~~^^^^^^^^^^^^^^^^^^^^^^^^^^^^^^^^^^^^^^^^
socket.gaierror: [Errno 8] nodename nor servname provided, or not known

During handling of the above exception, another exception occurred:

Traceback (most recent call last):
  File "/Library/Frameworks/Python.framework/Versions/3.13/lib/python3.13/site-packages/urllib3/connectionpool.py", line 716, in urlopen
    httplib_response = self._make_request(
        conn,
    ...<5 lines>...
        chunked=chunked,
    )
  File "/Library/Frameworks/Python.framework/Versions/3.13/lib/python3.13/site-packages/urllib3/connectionpool.py", line 404, in _make_request
    self._validate_conn(conn)
    ~~~~~~~~~~~~~~~~~~~^^^^^^
  File "/Library/Frameworks/Python.framework/Versions/3.13/lib/python3.13/site-packages/urllib3/connectionpool.py", line 1061, in _validate_conn
    conn.connect()
    ~~~~~~~~~~~~^^
  File "/Library/Frameworks/Python.framework/Versions/3.13/lib/python3.13/site-packages/urllib3/connection.py", line 363, in connect
    self.sock = conn = self._new_conn()
                       ~~~~~~~~~~~~~~^^
  File "/Library/Frameworks/Python.framework/Versions/3.13/lib/python3.13/site-packages/urllib3/connection.py", line 186, in _new_conn
    raise NewConnectionError(
        self, "Failed to establish a new connection: %s" % e
    )
urllib3.exceptions.NewConnectionError: <urllib3.connection.HTTPSConnection object at 0x105c33c50>: Failed to establish a new connection: [Errno 8] nodename nor servname provided, or not known

During handling of the above exception, another exception occurred:

Traceback (most recent call last):
  File "/Library/Frameworks/Python.framework/Versions/3.13/lib/python3.13/site-packages/requests/adapters.py", line 439, in send
    resp = conn.urlopen(
        method=request.method,
    ...<8 lines>...
        timeout=timeout
    )
  File "/Library/Frameworks/Python.framework/Versions/3.13/lib/python3.13/site-packages/urllib3/connectionpool.py", line 802, in urlopen
    retries = retries.increment(
        method, url, error=e, _pool=self, _stacktrace=sys.exc_info()[2]
    )
  File "/Library/Frameworks/Python.framework/Versions/3.13/lib/python3.13/site-packages/urllib3/util/retry.py", line 594, in increment
    raise MaxRetryError(_pool, url, error or ResponseError(cause))
urllib3.exceptions.MaxRetryError: HTTPSConnectionPool(host='auth.truedata.in', port=443): Max retries exceeded with url: /token (Caused by NewConnectionError('<urllib3.connection.HTTPSConnection object at 0x105c33c50>: Failed to establish a new connection: [Errno 8] nodename nor servname provided, or not known'))

During handling of the above exception, another exception occurred:

Traceback (most recent call last):
  File "/Users/aneeshviswanathan/Desktop/Updated_om_babaji_om /true_data_utils.py", line 44, in fetch_latest_ohlcv
    token = get_token()
  File "/Users/aneeshviswanathan/Desktop/Updated_om_babaji_om /true_data_utils.py", line 29, in get_token
    resp = requests.post(url, data=payload)
  File "/Library/Frameworks/Python.framework/Versions/3.13/lib/python3.13/site-packages/requests/api.py", line 119, in post
    return request('post', url, data=data, json=json, **kwargs)
  File "/Library/Frameworks/Python.framework/Versions/3.13/lib/python3.13/site-packages/requests/api.py", line 61, in request
    return session.request(method=method, url=url, **kwargs)
           ~~~~~~~~~~~~~~~^^^^^^^^^^^^^^^^^^^^^^^^^^^^^^^^^^
  File "/Library/Frameworks/Python.framework/Versions/3.13/lib/python3.13/site-packages/requests/sessions.py", line 542, in request
    resp = self.send(prep, **send_kwargs)
  File "/Library/Frameworks/Python.framework/Versions/3.13/lib/python3.13/site-packages/requests/sessions.py", line 655, in send
    r = adapter.send(request, **kwargs)
  File "/Library/Frameworks/Python.framework/Versions/3.13/lib/python3.13/site-packages/requests/adapters.py", line 516, in send
    raise ConnectionError(e, request=request)
requests.exceptions.ConnectionError: HTTPSConnectionPool(host='auth.truedata.in', port=443): Max retries exceeded with url: /token (Caused by NewConnectionError('<urllib3.connection.HTTPSConnection object at 0x105c33c50>: Failed to establish a new connection: [Errno 8] nodename nor servname provided, or not known'))
2025-06-25 08:11:05,728 [ERROR] true_data_utils: Attempt 2 fetch failed: HTTPSConnectionPool(host='auth.truedata.in', port=443): Max retries exceeded with url: /token (Caused by NewConnectionError('<urllib3.connection.HTTPSConnection object at 0x105c32990>: Failed to establish a new connection: [Errno 8] nodename nor servname provided, or not known'))
Traceback (most recent call last):
  File "/Library/Frameworks/Python.framework/Versions/3.13/lib/python3.13/site-packages/urllib3/connection.py", line 174, in _new_conn
    conn = connection.create_connection(
        (self._dns_host, self.port), self.timeout, **extra_kw
    )
  File "/Library/Frameworks/Python.framework/Versions/3.13/lib/python3.13/site-packages/urllib3/util/connection.py", line 72, in create_connection
    for res in socket.getaddrinfo(host, port, family, socket.SOCK_STREAM):
               ~~~~~~~~~~~~~~~~~~^^^^^^^^^^^^^^^^^^^^^^^^^^^^^^^^^^^^^^^^
  File "/Library/Frameworks/Python.framework/Versions/3.13/lib/python3.13/socket.py", line 975, in getaddrinfo
    for res in _socket.getaddrinfo(host, port, family, type, proto, flags):
               ~~~~~~~~~~~~~~~~~~~^^^^^^^^^^^^^^^^^^^^^^^^^^^^^^^^^^^^^^^^
socket.gaierror: [Errno 8] nodename nor servname provided, or not known

During handling of the above exception, another exception occurred:

Traceback (most recent call last):
  File "/Library/Frameworks/Python.framework/Versions/3.13/lib/python3.13/site-packages/urllib3/connectionpool.py", line 716, in urlopen
    httplib_response = self._make_request(
        conn,
    ...<5 lines>...
        chunked=chunked,
    )
  File "/Library/Frameworks/Python.framework/Versions/3.13/lib/python3.13/site-packages/urllib3/connectionpool.py", line 404, in _make_request
    self._validate_conn(conn)
    ~~~~~~~~~~~~~~~~~~~^^^^^^
  File "/Library/Frameworks/Python.framework/Versions/3.13/lib/python3.13/site-packages/urllib3/connectionpool.py", line 1061, in _validate_conn
    conn.connect()
    ~~~~~~~~~~~~^^
  File "/Library/Frameworks/Python.framework/Versions/3.13/lib/python3.13/site-packages/urllib3/connection.py", line 363, in connect
    self.sock = conn = self._new_conn()
                       ~~~~~~~~~~~~~~^^
  File "/Library/Frameworks/Python.framework/Versions/3.13/lib/python3.13/site-packages/urllib3/connection.py", line 186, in _new_conn
    raise NewConnectionError(
        self, "Failed to establish a new connection: %s" % e
    )
urllib3.exceptions.NewConnectionError: <urllib3.connection.HTTPSConnection object at 0x105c32990>: Failed to establish a new connection: [Errno 8] nodename nor servname provided, or not known

During handling of the above exception, another exception occurred:

Traceback (most recent call last):
  File "/Library/Frameworks/Python.framework/Versions/3.13/lib/python3.13/site-packages/requests/adapters.py", line 439, in send
    resp = conn.urlopen(
        method=request.method,
    ...<8 lines>...
        timeout=timeout
    )
  File "/Library/Frameworks/Python.framework/Versions/3.13/lib/python3.13/site-packages/urllib3/connectionpool.py", line 802, in urlopen
    retries = retries.increment(
        method, url, error=e, _pool=self, _stacktrace=sys.exc_info()[2]
    )
  File "/Library/Frameworks/Python.framework/Versions/3.13/lib/python3.13/site-packages/urllib3/util/retry.py", line 594, in increment
    raise MaxRetryError(_pool, url, error or ResponseError(cause))
urllib3.exceptions.MaxRetryError: HTTPSConnectionPool(host='auth.truedata.in', port=443): Max retries exceeded with url: /token (Caused by NewConnectionError('<urllib3.connection.HTTPSConnection object at 0x105c32990>: Failed to establish a new connection: [Errno 8] nodename nor servname provided, or not known'))

During handling of the above exception, another exception occurred:

Traceback (most recent call last):
  File "/Users/aneeshviswanathan/Desktop/Updated_om_babaji_om /true_data_utils.py", line 44, in fetch_latest_ohlcv
    token = get_token()
  File "/Users/aneeshviswanathan/Desktop/Updated_om_babaji_om /true_data_utils.py", line 29, in get_token
    resp = requests.post(url, data=payload)
  File "/Library/Frameworks/Python.framework/Versions/3.13/lib/python3.13/site-packages/requests/api.py", line 119, in post
    return request('post', url, data=data, json=json, **kwargs)
  File "/Library/Frameworks/Python.framework/Versions/3.13/lib/python3.13/site-packages/requests/api.py", line 61, in request
    return session.request(method=method, url=url, **kwargs)
           ~~~~~~~~~~~~~~~^^^^^^^^^^^^^^^^^^^^^^^^^^^^^^^^^^
  File "/Library/Frameworks/Python.framework/Versions/3.13/lib/python3.13/site-packages/requests/sessions.py", line 542, in request
    resp = self.send(prep, **send_kwargs)
  File "/Library/Frameworks/Python.framework/Versions/3.13/lib/python3.13/site-packages/requests/sessions.py", line 655, in send
    r = adapter.send(request, **kwargs)
  File "/Library/Frameworks/Python.framework/Versions/3.13/lib/python3.13/site-packages/requests/adapters.py", line 516, in send
    raise ConnectionError(e, request=request)
requests.exceptions.ConnectionError: HTTPSConnectionPool(host='auth.truedata.in', port=443): Max retries exceeded with url: /token (Caused by NewConnectionError('<urllib3.connection.HTTPSConnection object at 0x105c32990>: Failed to establish a new connection: [Errno 8] nodename nor servname provided, or not known'))
2025-06-25 08:11:10,758 [ERROR] true_data_utils: Attempt 3 fetch failed: HTTPSConnectionPool(host='auth.truedata.in', port=443): Max retries exceeded with url: /token (Caused by NewConnectionError('<urllib3.connection.HTTPSConnection object at 0x105c32d50>: Failed to establish a new connection: [Errno 8] nodename nor servname provided, or not known'))
Traceback (most recent call last):
  File "/Library/Frameworks/Python.framework/Versions/3.13/lib/python3.13/site-packages/urllib3/connection.py", line 174, in _new_conn
    conn = connection.create_connection(
        (self._dns_host, self.port), self.timeout, **extra_kw
    )
  File "/Library/Frameworks/Python.framework/Versions/3.13/lib/python3.13/site-packages/urllib3/util/connection.py", line 72, in create_connection
    for res in socket.getaddrinfo(host, port, family, socket.SOCK_STREAM):
               ~~~~~~~~~~~~~~~~~~^^^^^^^^^^^^^^^^^^^^^^^^^^^^^^^^^^^^^^^^
  File "/Library/Frameworks/Python.framework/Versions/3.13/lib/python3.13/socket.py", line 975, in getaddrinfo
    for res in _socket.getaddrinfo(host, port, family, type, proto, flags):
               ~~~~~~~~~~~~~~~~~~~^^^^^^^^^^^^^^^^^^^^^^^^^^^^^^^^^^^^^^^^
socket.gaierror: [Errno 8] nodename nor servname provided, or not known

During handling of the above exception, another exception occurred:

Traceback (most recent call last):
  File "/Library/Frameworks/Python.framework/Versions/3.13/lib/python3.13/site-packages/urllib3/connectionpool.py", line 716, in urlopen
    httplib_response = self._make_request(
        conn,
    ...<5 lines>...
        chunked=chunked,
    )
  File "/Library/Frameworks/Python.framework/Versions/3.13/lib/python3.13/site-packages/urllib3/connectionpool.py", line 404, in _make_request
    self._validate_conn(conn)
    ~~~~~~~~~~~~~~~~~~~^^^^^^
  File "/Library/Frameworks/Python.framework/Versions/3.13/lib/python3.13/site-packages/urllib3/connectionpool.py", line 1061, in _validate_conn
    conn.connect()
    ~~~~~~~~~~~~^^
  File "/Library/Frameworks/Python.framework/Versions/3.13/lib/python3.13/site-packages/urllib3/connection.py", line 363, in connect
    self.sock = conn = self._new_conn()
                       ~~~~~~~~~~~~~~^^
  File "/Library/Frameworks/Python.framework/Versions/3.13/lib/python3.13/site-packages/urllib3/connection.py", line 186, in _new_conn
    raise NewConnectionError(
        self, "Failed to establish a new connection: %s" % e
    )
urllib3.exceptions.NewConnectionError: <urllib3.connection.HTTPSConnection object at 0x105c32d50>: Failed to establish a new connection: [Errno 8] nodename nor servname provided, or not known

During handling of the above exception, another exception occurred:

Traceback (most recent call last):
  File "/Library/Frameworks/Python.framework/Versions/3.13/lib/python3.13/site-packages/requests/adapters.py", line 439, in send
    resp = conn.urlopen(
        method=request.method,
    ...<8 lines>...
        timeout=timeout
    )
  File "/Library/Frameworks/Python.framework/Versions/3.13/lib/python3.13/site-packages/urllib3/connectionpool.py", line 802, in urlopen
    retries = retries.increment(
        method, url, error=e, _pool=self, _stacktrace=sys.exc_info()[2]
    )
  File "/Library/Frameworks/Python.framework/Versions/3.13/lib/python3.13/site-packages/urllib3/util/retry.py", line 594, in increment
    raise MaxRetryError(_pool, url, error or ResponseError(cause))
urllib3.exceptions.MaxRetryError: HTTPSConnectionPool(host='auth.truedata.in', port=443): Max retries exceeded with url: /token (Caused by NewConnectionError('<urllib3.connection.HTTPSConnection object at 0x105c32d50>: Failed to establish a new connection: [Errno 8] nodename nor servname provided, or not known'))

During handling of the above exception, another exception occurred:

Traceback (most recent call last):
  File "/Users/aneeshviswanathan/Desktop/Updated_om_babaji_om /true_data_utils.py", line 44, in fetch_latest_ohlcv
    token = get_token()
  File "/Users/aneeshviswanathan/Desktop/Updated_om_babaji_om /true_data_utils.py", line 29, in get_token
    resp = requests.post(url, data=payload)
  File "/Library/Frameworks/Python.framework/Versions/3.13/lib/python3.13/site-packages/requests/api.py", line 119, in post
    return request('post', url, data=data, json=json, **kwargs)
  File "/Library/Frameworks/Python.framework/Versions/3.13/lib/python3.13/site-packages/requests/api.py", line 61, in request
    return session.request(method=method, url=url, **kwargs)
           ~~~~~~~~~~~~~~~^^^^^^^^^^^^^^^^^^^^^^^^^^^^^^^^^^
  File "/Library/Frameworks/Python.framework/Versions/3.13/lib/python3.13/site-packages/requests/sessions.py", line 542, in request
    resp = self.send(prep, **send_kwargs)
  File "/Library/Frameworks/Python.framework/Versions/3.13/lib/python3.13/site-packages/requests/sessions.py", line 655, in send
    r = adapter.send(request, **kwargs)
  File "/Library/Frameworks/Python.framework/Versions/3.13/lib/python3.13/site-packages/requests/adapters.py", line 516, in send
    raise ConnectionError(e, request=request)
requests.exceptions.ConnectionError: HTTPSConnectionPool(host='auth.truedata.in', port=443): Max retries exceeded with url: /token (Caused by NewConnectionError('<urllib3.connection.HTTPSConnection object at 0x105c32d50>: Failed to establish a new connection: [Errno 8] nodename nor servname provided, or not known'))
2025-06-25 08:11:10,767 [ERROR] true_data_utils: All TrueData fetch attempts failed
2025-06-25 08:12:02,154 [ERROR] telegram: Failed to send Telegram message: HTTPSConnectionPool(host='api.telegram.org', port=443): Max retries exceeded with url: /bot7325593988:AAGEeA3L01rmfHqFZ38cF070G1WOTkv-8JU/sendMessage?chat_id=6468675993&text=Heartbeat%3A+2025-06-25+08%3A12%3A02&parse_mode=HTML (Caused by NewConnectionError('<urllib3.connection.HTTPSConnection object at 0x1050aaa50>: Failed to establish a new connection: [Errno 8] nodename nor servname provided, or not known'))
2025-06-25 08:12:02,205 [ERROR] true_data_utils: Attempt 1 fetch failed: HTTPSConnectionPool(host='auth.truedata.in', port=443): Max retries exceeded with url: /token (Caused by NewConnectionError('<urllib3.connection.HTTPSConnection object at 0x105087890>: Failed to establish a new connection: [Errno 8] nodename nor servname provided, or not known'))
Traceback (most recent call last):
  File "/Library/Frameworks/Python.framework/Versions/3.13/lib/python3.13/site-packages/urllib3/connection.py", line 174, in _new_conn
    conn = connection.create_connection(
        (self._dns_host, self.port), self.timeout, **extra_kw
    )
  File "/Library/Frameworks/Python.framework/Versions/3.13/lib/python3.13/site-packages/urllib3/util/connection.py", line 72, in create_connection
    for res in socket.getaddrinfo(host, port, family, socket.SOCK_STREAM):
               ~~~~~~~~~~~~~~~~~~^^^^^^^^^^^^^^^^^^^^^^^^^^^^^^^^^^^^^^^^
  File "/Library/Frameworks/Python.framework/Versions/3.13/lib/python3.13/socket.py", line 975, in getaddrinfo
    for res in _socket.getaddrinfo(host, port, family, type, proto, flags):
               ~~~~~~~~~~~~~~~~~~~^^^^^^^^^^^^^^^^^^^^^^^^^^^^^^^^^^^^^^^^
socket.gaierror: [Errno 8] nodename nor servname provided, or not known

During handling of the above exception, another exception occurred:

Traceback (most recent call last):
  File "/Library/Frameworks/Python.framework/Versions/3.13/lib/python3.13/site-packages/urllib3/connectionpool.py", line 716, in urlopen
    httplib_response = self._make_request(
        conn,
    ...<5 lines>...
        chunked=chunked,
    )
  File "/Library/Frameworks/Python.framework/Versions/3.13/lib/python3.13/site-packages/urllib3/connectionpool.py", line 404, in _make_request
    self._validate_conn(conn)
    ~~~~~~~~~~~~~~~~~~~^^^^^^
  File "/Library/Frameworks/Python.framework/Versions/3.13/lib/python3.13/site-packages/urllib3/connectionpool.py", line 1061, in _validate_conn
    conn.connect()
    ~~~~~~~~~~~~^^
  File "/Library/Frameworks/Python.framework/Versions/3.13/lib/python3.13/site-packages/urllib3/connection.py", line 363, in connect
    self.sock = conn = self._new_conn()
                       ~~~~~~~~~~~~~~^^
  File "/Library/Frameworks/Python.framework/Versions/3.13/lib/python3.13/site-packages/urllib3/connection.py", line 186, in _new_conn
    raise NewConnectionError(
        self, "Failed to establish a new connection: %s" % e
    )
urllib3.exceptions.NewConnectionError: <urllib3.connection.HTTPSConnection object at 0x105087890>: Failed to establish a new connection: [Errno 8] nodename nor servname provided, or not known

During handling of the above exception, another exception occurred:

Traceback (most recent call last):
  File "/Library/Frameworks/Python.framework/Versions/3.13/lib/python3.13/site-packages/requests/adapters.py", line 439, in send
    resp = conn.urlopen(
        method=request.method,
    ...<8 lines>...
        timeout=timeout
    )
  File "/Library/Frameworks/Python.framework/Versions/3.13/lib/python3.13/site-packages/urllib3/connectionpool.py", line 802, in urlopen
    retries = retries.increment(
        method, url, error=e, _pool=self, _stacktrace=sys.exc_info()[2]
    )
  File "/Library/Frameworks/Python.framework/Versions/3.13/lib/python3.13/site-packages/urllib3/util/retry.py", line 594, in increment
    raise MaxRetryError(_pool, url, error or ResponseError(cause))
urllib3.exceptions.MaxRetryError: HTTPSConnectionPool(host='auth.truedata.in', port=443): Max retries exceeded with url: /token (Caused by NewConnectionError('<urllib3.connection.HTTPSConnection object at 0x105087890>: Failed to establish a new connection: [Errno 8] nodename nor servname provided, or not known'))

During handling of the above exception, another exception occurred:

Traceback (most recent call last):
  File "/Users/aneeshviswanathan/Desktop/Updated_om_babaji_om /true_data_utils.py", line 44, in fetch_latest_ohlcv
    token = get_token()
  File "/Users/aneeshviswanathan/Desktop/Updated_om_babaji_om /true_data_utils.py", line 29, in get_token
    resp = requests.post(url, data=payload)
  File "/Library/Frameworks/Python.framework/Versions/3.13/lib/python3.13/site-packages/requests/api.py", line 119, in post
    return request('post', url, data=data, json=json, **kwargs)
  File "/Library/Frameworks/Python.framework/Versions/3.13/lib/python3.13/site-packages/requests/api.py", line 61, in request
    return session.request(method=method, url=url, **kwargs)
           ~~~~~~~~~~~~~~~^^^^^^^^^^^^^^^^^^^^^^^^^^^^^^^^^^
  File "/Library/Frameworks/Python.framework/Versions/3.13/lib/python3.13/site-packages/requests/sessions.py", line 542, in request
    resp = self.send(prep, **send_kwargs)
  File "/Library/Frameworks/Python.framework/Versions/3.13/lib/python3.13/site-packages/requests/sessions.py", line 655, in send
    r = adapter.send(request, **kwargs)
  File "/Library/Frameworks/Python.framework/Versions/3.13/lib/python3.13/site-packages/requests/adapters.py", line 516, in send
    raise ConnectionError(e, request=request)
requests.exceptions.ConnectionError: HTTPSConnectionPool(host='auth.truedata.in', port=443): Max retries exceeded with url: /token (Caused by NewConnectionError('<urllib3.connection.HTTPSConnection object at 0x105087890>: Failed to establish a new connection: [Errno 8] nodename nor servname provided, or not known'))
2025-06-25 08:12:07,221 [ERROR] true_data_utils: Attempt 2 fetch failed: HTTPSConnectionPool(host='auth.truedata.in', port=443): Max retries exceeded with url: /token (Caused by NewConnectionError('<urllib3.connection.HTTPSConnection object at 0x105086c10>: Failed to establish a new connection: [Errno 8] nodename nor servname provided, or not known'))
Traceback (most recent call last):
  File "/Library/Frameworks/Python.framework/Versions/3.13/lib/python3.13/site-packages/urllib3/connection.py", line 174, in _new_conn
    conn = connection.create_connection(
        (self._dns_host, self.port), self.timeout, **extra_kw
    )
  File "/Library/Frameworks/Python.framework/Versions/3.13/lib/python3.13/site-packages/urllib3/util/connection.py", line 72, in create_connection
    for res in socket.getaddrinfo(host, port, family, socket.SOCK_STREAM):
               ~~~~~~~~~~~~~~~~~~^^^^^^^^^^^^^^^^^^^^^^^^^^^^^^^^^^^^^^^^
  File "/Library/Frameworks/Python.framework/Versions/3.13/lib/python3.13/socket.py", line 975, in getaddrinfo
    for res in _socket.getaddrinfo(host, port, family, type, proto, flags):
               ~~~~~~~~~~~~~~~~~~~^^^^^^^^^^^^^^^^^^^^^^^^^^^^^^^^^^^^^^^^
socket.gaierror: [Errno 8] nodename nor servname provided, or not known

During handling of the above exception, another exception occurred:

Traceback (most recent call last):
  File "/Library/Frameworks/Python.framework/Versions/3.13/lib/python3.13/site-packages/urllib3/connectionpool.py", line 716, in urlopen
    httplib_response = self._make_request(
        conn,
    ...<5 lines>...
        chunked=chunked,
    )
  File "/Library/Frameworks/Python.framework/Versions/3.13/lib/python3.13/site-packages/urllib3/connectionpool.py", line 404, in _make_request
    self._validate_conn(conn)
    ~~~~~~~~~~~~~~~~~~~^^^^^^
  File "/Library/Frameworks/Python.framework/Versions/3.13/lib/python3.13/site-packages/urllib3/connectionpool.py", line 1061, in _validate_conn
    conn.connect()
    ~~~~~~~~~~~~^^
  File "/Library/Frameworks/Python.framework/Versions/3.13/lib/python3.13/site-packages/urllib3/connection.py", line 363, in connect
    self.sock = conn = self._new_conn()
                       ~~~~~~~~~~~~~~^^
  File "/Library/Frameworks/Python.framework/Versions/3.13/lib/python3.13/site-packages/urllib3/connection.py", line 186, in _new_conn
    raise NewConnectionError(
        self, "Failed to establish a new connection: %s" % e
    )
urllib3.exceptions.NewConnectionError: <urllib3.connection.HTTPSConnection object at 0x105086c10>: Failed to establish a new connection: [Errno 8] nodename nor servname provided, or not known

During handling of the above exception, another exception occurred:

Traceback (most recent call last):
  File "/Library/Frameworks/Python.framework/Versions/3.13/lib/python3.13/site-packages/requests/adapters.py", line 439, in send
    resp = conn.urlopen(
        method=request.method,
    ...<8 lines>...
        timeout=timeout
    )
  File "/Library/Frameworks/Python.framework/Versions/3.13/lib/python3.13/site-packages/urllib3/connectionpool.py", line 802, in urlopen
    retries = retries.increment(
        method, url, error=e, _pool=self, _stacktrace=sys.exc_info()[2]
    )
  File "/Library/Frameworks/Python.framework/Versions/3.13/lib/python3.13/site-packages/urllib3/util/retry.py", line 594, in increment
    raise MaxRetryError(_pool, url, error or ResponseError(cause))
urllib3.exceptions.MaxRetryError: HTTPSConnectionPool(host='auth.truedata.in', port=443): Max retries exceeded with url: /token (Caused by NewConnectionError('<urllib3.connection.HTTPSConnection object at 0x105086c10>: Failed to establish a new connection: [Errno 8] nodename nor servname provided, or not known'))

During handling of the above exception, another exception occurred:

Traceback (most recent call last):
  File "/Users/aneeshviswanathan/Desktop/Updated_om_babaji_om /true_data_utils.py", line 44, in fetch_latest_ohlcv
    token = get_token()
  File "/Users/aneeshviswanathan/Desktop/Updated_om_babaji_om /true_data_utils.py", line 29, in get_token
    resp = requests.post(url, data=payload)
  File "/Library/Frameworks/Python.framework/Versions/3.13/lib/python3.13/site-packages/requests/api.py", line 119, in post
    return request('post', url, data=data, json=json, **kwargs)
  File "/Library/Frameworks/Python.framework/Versions/3.13/lib/python3.13/site-packages/requests/api.py", line 61, in request
    return session.request(method=method, url=url, **kwargs)
           ~~~~~~~~~~~~~~~^^^^^^^^^^^^^^^^^^^^^^^^^^^^^^^^^^
  File "/Library/Frameworks/Python.framework/Versions/3.13/lib/python3.13/site-packages/requests/sessions.py", line 542, in request
    resp = self.send(prep, **send_kwargs)
  File "/Library/Frameworks/Python.framework/Versions/3.13/lib/python3.13/site-packages/requests/sessions.py", line 655, in send
    r = adapter.send(request, **kwargs)
  File "/Library/Frameworks/Python.framework/Versions/3.13/lib/python3.13/site-packages/requests/adapters.py", line 516, in send
    raise ConnectionError(e, request=request)
requests.exceptions.ConnectionError: HTTPSConnectionPool(host='auth.truedata.in', port=443): Max retries exceeded with url: /token (Caused by NewConnectionError('<urllib3.connection.HTTPSConnection object at 0x105086c10>: Failed to establish a new connection: [Errno 8] nodename nor servname provided, or not known'))
2025-06-25 08:12:12,238 [ERROR] true_data_utils: Attempt 3 fetch failed: HTTPSConnectionPool(host='auth.truedata.in', port=443): Max retries exceeded with url: /token (Caused by NewConnectionError('<urllib3.connection.HTTPSConnection object at 0x105087390>: Failed to establish a new connection: [Errno 8] nodename nor servname provided, or not known'))
Traceback (most recent call last):
  File "/Library/Frameworks/Python.framework/Versions/3.13/lib/python3.13/site-packages/urllib3/connection.py", line 174, in _new_conn
    conn = connection.create_connection(
        (self._dns_host, self.port), self.timeout, **extra_kw
    )
  File "/Library/Frameworks/Python.framework/Versions/3.13/lib/python3.13/site-packages/urllib3/util/connection.py", line 72, in create_connection
    for res in socket.getaddrinfo(host, port, family, socket.SOCK_STREAM):
               ~~~~~~~~~~~~~~~~~~^^^^^^^^^^^^^^^^^^^^^^^^^^^^^^^^^^^^^^^^
  File "/Library/Frameworks/Python.framework/Versions/3.13/lib/python3.13/socket.py", line 975, in getaddrinfo
    for res in _socket.getaddrinfo(host, port, family, type, proto, flags):
               ~~~~~~~~~~~~~~~~~~~^^^^^^^^^^^^^^^^^^^^^^^^^^^^^^^^^^^^^^^^
socket.gaierror: [Errno 8] nodename nor servname provided, or not known

During handling of the above exception, another exception occurred:

Traceback (most recent call last):
  File "/Library/Frameworks/Python.framework/Versions/3.13/lib/python3.13/site-packages/urllib3/connectionpool.py", line 716, in urlopen
    httplib_response = self._make_request(
        conn,
    ...<5 lines>...
        chunked=chunked,
    )
  File "/Library/Frameworks/Python.framework/Versions/3.13/lib/python3.13/site-packages/urllib3/connectionpool.py", line 404, in _make_request
    self._validate_conn(conn)
    ~~~~~~~~~~~~~~~~~~~^^^^^^
  File "/Library/Frameworks/Python.framework/Versions/3.13/lib/python3.13/site-packages/urllib3/connectionpool.py", line 1061, in _validate_conn
    conn.connect()
    ~~~~~~~~~~~~^^
  File "/Library/Frameworks/Python.framework/Versions/3.13/lib/python3.13/site-packages/urllib3/connection.py", line 363, in connect
    self.sock = conn = self._new_conn()
                       ~~~~~~~~~~~~~~^^
  File "/Library/Frameworks/Python.framework/Versions/3.13/lib/python3.13/site-packages/urllib3/connection.py", line 186, in _new_conn
    raise NewConnectionError(
        self, "Failed to establish a new connection: %s" % e
    )
urllib3.exceptions.NewConnectionError: <urllib3.connection.HTTPSConnection object at 0x105087390>: Failed to establish a new connection: [Errno 8] nodename nor servname provided, or not known

During handling of the above exception, another exception occurred:

Traceback (most recent call last):
  File "/Library/Frameworks/Python.framework/Versions/3.13/lib/python3.13/site-packages/requests/adapters.py", line 439, in send
    resp = conn.urlopen(
        method=request.method,
    ...<8 lines>...
        timeout=timeout
    )
  File "/Library/Frameworks/Python.framework/Versions/3.13/lib/python3.13/site-packages/urllib3/connectionpool.py", line 802, in urlopen
    retries = retries.increment(
        method, url, error=e, _pool=self, _stacktrace=sys.exc_info()[2]
    )
  File "/Library/Frameworks/Python.framework/Versions/3.13/lib/python3.13/site-packages/urllib3/util/retry.py", line 594, in increment
    raise MaxRetryError(_pool, url, error or ResponseError(cause))
urllib3.exceptions.MaxRetryError: HTTPSConnectionPool(host='auth.truedata.in', port=443): Max retries exceeded with url: /token (Caused by NewConnectionError('<urllib3.connection.HTTPSConnection object at 0x105087390>: Failed to establish a new connection: [Errno 8] nodename nor servname provided, or not known'))

During handling of the above exception, another exception occurred:

Traceback (most recent call last):
  File "/Users/aneeshviswanathan/Desktop/Updated_om_babaji_om /true_data_utils.py", line 44, in fetch_latest_ohlcv
    token = get_token()
  File "/Users/aneeshviswanathan/Desktop/Updated_om_babaji_om /true_data_utils.py", line 29, in get_token
    resp = requests.post(url, data=payload)
  File "/Library/Frameworks/Python.framework/Versions/3.13/lib/python3.13/site-packages/requests/api.py", line 119, in post
    return request('post', url, data=data, json=json, **kwargs)
  File "/Library/Frameworks/Python.framework/Versions/3.13/lib/python3.13/site-packages/requests/api.py", line 61, in request
    return session.request(method=method, url=url, **kwargs)
           ~~~~~~~~~~~~~~~^^^^^^^^^^^^^^^^^^^^^^^^^^^^^^^^^^
  File "/Library/Frameworks/Python.framework/Versions/3.13/lib/python3.13/site-packages/requests/sessions.py", line 542, in request
    resp = self.send(prep, **send_kwargs)
  File "/Library/Frameworks/Python.framework/Versions/3.13/lib/python3.13/site-packages/requests/sessions.py", line 655, in send
    r = adapter.send(request, **kwargs)
  File "/Library/Frameworks/Python.framework/Versions/3.13/lib/python3.13/site-packages/requests/adapters.py", line 516, in send
    raise ConnectionError(e, request=request)
requests.exceptions.ConnectionError: HTTPSConnectionPool(host='auth.truedata.in', port=443): Max retries exceeded with url: /token (Caused by NewConnectionError('<urllib3.connection.HTTPSConnection object at 0x105087390>: Failed to establish a new connection: [Errno 8] nodename nor servname provided, or not known'))
2025-06-25 08:12:12,247 [ERROR] true_data_utils: All TrueData fetch attempts failed
2025-06-25 08:13:00,408 [ERROR] true_data_utils: Attempt 1 fetch failed: HTTPSConnectionPool(host='auth.truedata.in', port=443): Max retries exceeded with url: /token (Caused by NewConnectionError('<urllib3.connection.HTTPSConnection object at 0x105086990>: Failed to establish a new connection: [Errno 8] nodename nor servname provided, or not known'))
Traceback (most recent call last):
  File "/Library/Frameworks/Python.framework/Versions/3.13/lib/python3.13/site-packages/urllib3/connection.py", line 174, in _new_conn
    conn = connection.create_connection(
        (self._dns_host, self.port), self.timeout, **extra_kw
    )
  File "/Library/Frameworks/Python.framework/Versions/3.13/lib/python3.13/site-packages/urllib3/util/connection.py", line 72, in create_connection
    for res in socket.getaddrinfo(host, port, family, socket.SOCK_STREAM):
               ~~~~~~~~~~~~~~~~~~^^^^^^^^^^^^^^^^^^^^^^^^^^^^^^^^^^^^^^^^
  File "/Library/Frameworks/Python.framework/Versions/3.13/lib/python3.13/socket.py", line 975, in getaddrinfo
    for res in _socket.getaddrinfo(host, port, family, type, proto, flags):
               ~~~~~~~~~~~~~~~~~~~^^^^^^^^^^^^^^^^^^^^^^^^^^^^^^^^^^^^^^^^
socket.gaierror: [Errno 8] nodename nor servname provided, or not known

During handling of the above exception, another exception occurred:

Traceback (most recent call last):
  File "/Library/Frameworks/Python.framework/Versions/3.13/lib/python3.13/site-packages/urllib3/connectionpool.py", line 716, in urlopen
    httplib_response = self._make_request(
        conn,
    ...<5 lines>...
        chunked=chunked,
    )
  File "/Library/Frameworks/Python.framework/Versions/3.13/lib/python3.13/site-packages/urllib3/connectionpool.py", line 404, in _make_request
    self._validate_conn(conn)
    ~~~~~~~~~~~~~~~~~~~^^^^^^
  File "/Library/Frameworks/Python.framework/Versions/3.13/lib/python3.13/site-packages/urllib3/connectionpool.py", line 1061, in _validate_conn
    conn.connect()
    ~~~~~~~~~~~~^^
  File "/Library/Frameworks/Python.framework/Versions/3.13/lib/python3.13/site-packages/urllib3/connection.py", line 363, in connect
    self.sock = conn = self._new_conn()
                       ~~~~~~~~~~~~~~^^
  File "/Library/Frameworks/Python.framework/Versions/3.13/lib/python3.13/site-packages/urllib3/connection.py", line 186, in _new_conn
    raise NewConnectionError(
        self, "Failed to establish a new connection: %s" % e
    )
urllib3.exceptions.NewConnectionError: <urllib3.connection.HTTPSConnection object at 0x105086990>: Failed to establish a new connection: [Errno 8] nodename nor servname provided, or not known

During handling of the above exception, another exception occurred:

Traceback (most recent call last):
  File "/Library/Frameworks/Python.framework/Versions/3.13/lib/python3.13/site-packages/requests/adapters.py", line 439, in send
    resp = conn.urlopen(
        method=request.method,
    ...<8 lines>...
        timeout=timeout
    )
  File "/Library/Frameworks/Python.framework/Versions/3.13/lib/python3.13/site-packages/urllib3/connectionpool.py", line 802, in urlopen
    retries = retries.increment(
        method, url, error=e, _pool=self, _stacktrace=sys.exc_info()[2]
    )
  File "/Library/Frameworks/Python.framework/Versions/3.13/lib/python3.13/site-packages/urllib3/util/retry.py", line 594, in increment
    raise MaxRetryError(_pool, url, error or ResponseError(cause))
urllib3.exceptions.MaxRetryError: HTTPSConnectionPool(host='auth.truedata.in', port=443): Max retries exceeded with url: /token (Caused by NewConnectionError('<urllib3.connection.HTTPSConnection object at 0x105086990>: Failed to establish a new connection: [Errno 8] nodename nor servname provided, or not known'))

During handling of the above exception, another exception occurred:

Traceback (most recent call last):
  File "/Users/aneeshviswanathan/Desktop/Updated_om_babaji_om /true_data_utils.py", line 44, in fetch_latest_ohlcv
    token = get_token()
  File "/Users/aneeshviswanathan/Desktop/Updated_om_babaji_om /true_data_utils.py", line 29, in get_token
    resp = requests.post(url, data=payload)
  File "/Library/Frameworks/Python.framework/Versions/3.13/lib/python3.13/site-packages/requests/api.py", line 119, in post
    return request('post', url, data=data, json=json, **kwargs)
  File "/Library/Frameworks/Python.framework/Versions/3.13/lib/python3.13/site-packages/requests/api.py", line 61, in request
    return session.request(method=method, url=url, **kwargs)
           ~~~~~~~~~~~~~~~^^^^^^^^^^^^^^^^^^^^^^^^^^^^^^^^^^
  File "/Library/Frameworks/Python.framework/Versions/3.13/lib/python3.13/site-packages/requests/sessions.py", line 542, in request
    resp = self.send(prep, **send_kwargs)
  File "/Library/Frameworks/Python.framework/Versions/3.13/lib/python3.13/site-packages/requests/sessions.py", line 655, in send
    r = adapter.send(request, **kwargs)
  File "/Library/Frameworks/Python.framework/Versions/3.13/lib/python3.13/site-packages/requests/adapters.py", line 516, in send
    raise ConnectionError(e, request=request)
requests.exceptions.ConnectionError: HTTPSConnectionPool(host='auth.truedata.in', port=443): Max retries exceeded with url: /token (Caused by NewConnectionError('<urllib3.connection.HTTPSConnection object at 0x105086990>: Failed to establish a new connection: [Errno 8] nodename nor servname provided, or not known'))
2025-06-25 08:13:05,423 [ERROR] true_data_utils: Attempt 2 fetch failed: HTTPSConnectionPool(host='auth.truedata.in', port=443): Max retries exceeded with url: /token (Caused by NewConnectionError('<urllib3.connection.HTTPSConnection object at 0x105087750>: Failed to establish a new connection: [Errno 8] nodename nor servname provided, or not known'))
Traceback (most recent call last):
  File "/Library/Frameworks/Python.framework/Versions/3.13/lib/python3.13/site-packages/urllib3/connection.py", line 174, in _new_conn
    conn = connection.create_connection(
        (self._dns_host, self.port), self.timeout, **extra_kw
    )
  File "/Library/Frameworks/Python.framework/Versions/3.13/lib/python3.13/site-packages/urllib3/util/connection.py", line 72, in create_connection
    for res in socket.getaddrinfo(host, port, family, socket.SOCK_STREAM):
               ~~~~~~~~~~~~~~~~~~^^^^^^^^^^^^^^^^^^^^^^^^^^^^^^^^^^^^^^^^
  File "/Library/Frameworks/Python.framework/Versions/3.13/lib/python3.13/socket.py", line 975, in getaddrinfo
    for res in _socket.getaddrinfo(host, port, family, type, proto, flags):
               ~~~~~~~~~~~~~~~~~~~^^^^^^^^^^^^^^^^^^^^^^^^^^^^^^^^^^^^^^^^
socket.gaierror: [Errno 8] nodename nor servname provided, or not known

During handling of the above exception, another exception occurred:

Traceback (most recent call last):
  File "/Library/Frameworks/Python.framework/Versions/3.13/lib/python3.13/site-packages/urllib3/connectionpool.py", line 716, in urlopen
    httplib_response = self._make_request(
        conn,
    ...<5 lines>...
        chunked=chunked,
    )
  File "/Library/Frameworks/Python.framework/Versions/3.13/lib/python3.13/site-packages/urllib3/connectionpool.py", line 404, in _make_request
    self._validate_conn(conn)
    ~~~~~~~~~~~~~~~~~~~^^^^^^
  File "/Library/Frameworks/Python.framework/Versions/3.13/lib/python3.13/site-packages/urllib3/connectionpool.py", line 1061, in _validate_conn
    conn.connect()
    ~~~~~~~~~~~~^^
  File "/Library/Frameworks/Python.framework/Versions/3.13/lib/python3.13/site-packages/urllib3/connection.py", line 363, in connect
    self.sock = conn = self._new_conn()
                       ~~~~~~~~~~~~~~^^
  File "/Library/Frameworks/Python.framework/Versions/3.13/lib/python3.13/site-packages/urllib3/connection.py", line 186, in _new_conn
    raise NewConnectionError(
        self, "Failed to establish a new connection: %s" % e
    )
urllib3.exceptions.NewConnectionError: <urllib3.connection.HTTPSConnection object at 0x105087750>: Failed to establish a new connection: [Errno 8] nodename nor servname provided, or not known

During handling of the above exception, another exception occurred:

Traceback (most recent call last):
  File "/Library/Frameworks/Python.framework/Versions/3.13/lib/python3.13/site-packages/requests/adapters.py", line 439, in send
    resp = conn.urlopen(
        method=request.method,
    ...<8 lines>...
        timeout=timeout
    )
  File "/Library/Frameworks/Python.framework/Versions/3.13/lib/python3.13/site-packages/urllib3/connectionpool.py", line 802, in urlopen
    retries = retries.increment(
        method, url, error=e, _pool=self, _stacktrace=sys.exc_info()[2]
    )
  File "/Library/Frameworks/Python.framework/Versions/3.13/lib/python3.13/site-packages/urllib3/util/retry.py", line 594, in increment
    raise MaxRetryError(_pool, url, error or ResponseError(cause))
urllib3.exceptions.MaxRetryError: HTTPSConnectionPool(host='auth.truedata.in', port=443): Max retries exceeded with url: /token (Caused by NewConnectionError('<urllib3.connection.HTTPSConnection object at 0x105087750>: Failed to establish a new connection: [Errno 8] nodename nor servname provided, or not known'))

During handling of the above exception, another exception occurred:

Traceback (most recent call last):
  File "/Users/aneeshviswanathan/Desktop/Updated_om_babaji_om /true_data_utils.py", line 44, in fetch_latest_ohlcv
    token = get_token()
  File "/Users/aneeshviswanathan/Desktop/Updated_om_babaji_om /true_data_utils.py", line 29, in get_token
    resp = requests.post(url, data=payload)
  File "/Library/Frameworks/Python.framework/Versions/3.13/lib/python3.13/site-packages/requests/api.py", line 119, in post
    return request('post', url, data=data, json=json, **kwargs)
  File "/Library/Frameworks/Python.framework/Versions/3.13/lib/python3.13/site-packages/requests/api.py", line 61, in request
    return session.request(method=method, url=url, **kwargs)
           ~~~~~~~~~~~~~~~^^^^^^^^^^^^^^^^^^^^^^^^^^^^^^^^^^
  File "/Library/Frameworks/Python.framework/Versions/3.13/lib/python3.13/site-packages/requests/sessions.py", line 542, in request
    resp = self.send(prep, **send_kwargs)
  File "/Library/Frameworks/Python.framework/Versions/3.13/lib/python3.13/site-packages/requests/sessions.py", line 655, in send
    r = adapter.send(request, **kwargs)
  File "/Library/Frameworks/Python.framework/Versions/3.13/lib/python3.13/site-packages/requests/adapters.py", line 516, in send
    raise ConnectionError(e, request=request)
requests.exceptions.ConnectionError: HTTPSConnectionPool(host='auth.truedata.in', port=443): Max retries exceeded with url: /token (Caused by NewConnectionError('<urllib3.connection.HTTPSConnection object at 0x105087750>: Failed to establish a new connection: [Errno 8] nodename nor servname provided, or not known'))
2025-06-25 08:13:10,438 [ERROR] true_data_utils: Attempt 3 fetch failed: HTTPSConnectionPool(host='auth.truedata.in', port=443): Max retries exceeded with url: /token (Caused by NewConnectionError('<urllib3.connection.HTTPSConnection object at 0x105087250>: Failed to establish a new connection: [Errno 8] nodename nor servname provided, or not known'))
Traceback (most recent call last):
  File "/Library/Frameworks/Python.framework/Versions/3.13/lib/python3.13/site-packages/urllib3/connection.py", line 174, in _new_conn
    conn = connection.create_connection(
        (self._dns_host, self.port), self.timeout, **extra_kw
    )
  File "/Library/Frameworks/Python.framework/Versions/3.13/lib/python3.13/site-packages/urllib3/util/connection.py", line 72, in create_connection
    for res in socket.getaddrinfo(host, port, family, socket.SOCK_STREAM):
               ~~~~~~~~~~~~~~~~~~^^^^^^^^^^^^^^^^^^^^^^^^^^^^^^^^^^^^^^^^
  File "/Library/Frameworks/Python.framework/Versions/3.13/lib/python3.13/socket.py", line 975, in getaddrinfo
    for res in _socket.getaddrinfo(host, port, family, type, proto, flags):
               ~~~~~~~~~~~~~~~~~~~^^^^^^^^^^^^^^^^^^^^^^^^^^^^^^^^^^^^^^^^
socket.gaierror: [Errno 8] nodename nor servname provided, or not known

During handling of the above exception, another exception occurred:

Traceback (most recent call last):
  File "/Library/Frameworks/Python.framework/Versions/3.13/lib/python3.13/site-packages/urllib3/connectionpool.py", line 716, in urlopen
    httplib_response = self._make_request(
        conn,
    ...<5 lines>...
        chunked=chunked,
    )
  File "/Library/Frameworks/Python.framework/Versions/3.13/lib/python3.13/site-packages/urllib3/connectionpool.py", line 404, in _make_request
    self._validate_conn(conn)
    ~~~~~~~~~~~~~~~~~~~^^^^^^
  File "/Library/Frameworks/Python.framework/Versions/3.13/lib/python3.13/site-packages/urllib3/connectionpool.py", line 1061, in _validate_conn
    conn.connect()
    ~~~~~~~~~~~~^^
  File "/Library/Frameworks/Python.framework/Versions/3.13/lib/python3.13/site-packages/urllib3/connection.py", line 363, in connect
    self.sock = conn = self._new_conn()
                       ~~~~~~~~~~~~~~^^
  File "/Library/Frameworks/Python.framework/Versions/3.13/lib/python3.13/site-packages/urllib3/connection.py", line 186, in _new_conn
    raise NewConnectionError(
        self, "Failed to establish a new connection: %s" % e
    )
urllib3.exceptions.NewConnectionError: <urllib3.connection.HTTPSConnection object at 0x105087250>: Failed to establish a new connection: [Errno 8] nodename nor servname provided, or not known

During handling of the above exception, another exception occurred:

Traceback (most recent call last):
  File "/Library/Frameworks/Python.framework/Versions/3.13/lib/python3.13/site-packages/requests/adapters.py", line 439, in send
    resp = conn.urlopen(
        method=request.method,
    ...<8 lines>...
        timeout=timeout
    )
  File "/Library/Frameworks/Python.framework/Versions/3.13/lib/python3.13/site-packages/urllib3/connectionpool.py", line 802, in urlopen
    retries = retries.increment(
        method, url, error=e, _pool=self, _stacktrace=sys.exc_info()[2]
    )
  File "/Library/Frameworks/Python.framework/Versions/3.13/lib/python3.13/site-packages/urllib3/util/retry.py", line 594, in increment
    raise MaxRetryError(_pool, url, error or ResponseError(cause))
urllib3.exceptions.MaxRetryError: HTTPSConnectionPool(host='auth.truedata.in', port=443): Max retries exceeded with url: /token (Caused by NewConnectionError('<urllib3.connection.HTTPSConnection object at 0x105087250>: Failed to establish a new connection: [Errno 8] nodename nor servname provided, or not known'))

During handling of the above exception, another exception occurred:

Traceback (most recent call last):
  File "/Users/aneeshviswanathan/Desktop/Updated_om_babaji_om /true_data_utils.py", line 44, in fetch_latest_ohlcv
    token = get_token()
  File "/Users/aneeshviswanathan/Desktop/Updated_om_babaji_om /true_data_utils.py", line 29, in get_token
    resp = requests.post(url, data=payload)
  File "/Library/Frameworks/Python.framework/Versions/3.13/lib/python3.13/site-packages/requests/api.py", line 119, in post
    return request('post', url, data=data, json=json, **kwargs)
  File "/Library/Frameworks/Python.framework/Versions/3.13/lib/python3.13/site-packages/requests/api.py", line 61, in request
    return session.request(method=method, url=url, **kwargs)
           ~~~~~~~~~~~~~~~^^^^^^^^^^^^^^^^^^^^^^^^^^^^^^^^^^
  File "/Library/Frameworks/Python.framework/Versions/3.13/lib/python3.13/site-packages/requests/sessions.py", line 542, in request
    resp = self.send(prep, **send_kwargs)
  File "/Library/Frameworks/Python.framework/Versions/3.13/lib/python3.13/site-packages/requests/sessions.py", line 655, in send
    r = adapter.send(request, **kwargs)
  File "/Library/Frameworks/Python.framework/Versions/3.13/lib/python3.13/site-packages/requests/adapters.py", line 516, in send
    raise ConnectionError(e, request=request)
requests.exceptions.ConnectionError: HTTPSConnectionPool(host='auth.truedata.in', port=443): Max retries exceeded with url: /token (Caused by NewConnectionError('<urllib3.connection.HTTPSConnection object at 0x105087250>: Failed to establish a new connection: [Errno 8] nodename nor servname provided, or not known'))
2025-06-25 08:13:10,443 [ERROR] true_data_utils: All TrueData fetch attempts failed
2025-06-25 08:14:01,066 [ERROR] true_data_utils: TrueData missing cols: {'No data exists for BANKNIFTY25JUNFUT'}
2025-06-25 08:15:00,586 [ERROR] true_data_utils: TrueData missing cols: {'No data exists for BANKNIFTY25JUNFUT'}
2025-06-25 08:16:01,196 [ERROR] true_data_utils: TrueData missing cols: {'No data exists for BANKNIFTY25JUNFUT'}
2025-06-25 08:17:00,750 [ERROR] true_data_utils: TrueData missing cols: {'No data exists for BANKNIFTY25JUNFUT'}
2025-06-25 08:18:56,864 [ERROR] true_data_utils: TrueData missing cols: {'No data exists for BANKNIFTY25JUNFUT'}
2025-06-25 08:19:01,481 [ERROR] true_data_utils: TrueData missing cols: {'No data exists for BANKNIFTY25JUNFUT'}
2025-06-25 08:27:57,967 [ERROR] true_data_utils: TrueData missing cols: {'No data exists for BANKNIFTY25JUNFUT'}
2025-06-25 08:28:00,497 [ERROR] true_data_utils: TrueData missing cols: {'No data exists for BANKNIFTY25JUNFUT'}
2025-06-25 08:29:01,088 [ERROR] true_data_utils: TrueData missing cols: {'No data exists for BANKNIFTY25JUNFUT'}
2025-06-25 08:30:00,664 [ERROR] true_data_utils: TrueData missing cols: {'No data exists for BANKNIFTY25JUNFUT'}
2025-06-25 08:31:01,166 [ERROR] true_data_utils: TrueData missing cols: {'No data exists for BANKNIFTY25JUNFUT'}
2025-06-25 08:32:00,885 [ERROR] true_data_utils: TrueData missing cols: {'No data exists for BANKNIFTY25JUNFUT'}
2025-06-25 08:33:01,375 [ERROR] true_data_utils: TrueData missing cols: {'No data exists for BANKNIFTY25JUNFUT'}
2025-06-25 08:34:01,155 [ERROR] true_data_utils: TrueData missing cols: {'No data exists for BANKNIFTY25JUNFUT'}
2025-06-25 08:35:00,746 [ERROR] true_data_utils: TrueData missing cols: {'No data exists for BANKNIFTY25JUNFUT'}
2025-06-25 08:36:01,314 [ERROR] true_data_utils: TrueData missing cols: {'No data exists for BANKNIFTY25JUNFUT'}
2025-06-25 08:37:00,868 [ERROR] true_data_utils: TrueData missing cols: {'No data exists for BANKNIFTY25JUNFUT'}
2025-06-25 08:38:01,516 [ERROR] true_data_utils: TrueData missing cols: {'No data exists for BANKNIFTY25JUNFUT'}
2025-06-25 08:41:38,180 [ERROR] true_data_utils: TrueData missing cols: {'No data exists for BANKNIFTY25JUNFUT'}
2025-06-25 08:42:00,667 [ERROR] true_data_utils: TrueData missing cols: {'No data exists for BANKNIFTY25JUNFUT'}
2025-06-25 09:10:18,823 [ERROR] true_data_utils: TrueData missing cols: {'No data exists for BANKNIFTY25JUNFUT'}
2025-06-25 09:11:01,438 [ERROR] true_data_utils: TrueData missing cols: {'No data exists for BANKNIFTY25JUNFUT'}
2025-06-25 09:12:01,017 [ERROR] true_data_utils: TrueData missing cols: {'No data exists for BANKNIFTY25JUNFUT'}
2025-06-25 09:13:00,630 [ERROR] true_data_utils: TrueData missing cols: {'No data exists for BANKNIFTY25JUNFUT'}
2025-06-25 09:14:01,272 [ERROR] true_data_utils: TrueData missing cols: {'No data exists for BANKNIFTY25JUNFUT'}
2025-06-25 09:15:00,959 [ERROR] true_data_utils: TrueData missing cols: {'No data exists for BANKNIFTY25JUNFUT'}
2025-06-25 18:00:01,408 [ERROR] true_data_utils: TrueData missing cols: {'No data exists for BANKNIFTY25JUNFUT'}
2025-06-25 18:01:01,038 [ERROR] true_data_utils: TrueData missing cols: {'No data exists for BANKNIFTY25JUNFUT'}
2025-06-25 18:02:00,712 [ERROR] true_data_utils: TrueData missing cols: {'No data exists for BANKNIFTY25JUNFUT'}
2025-06-25 18:03:01,404 [ERROR] true_data_utils: TrueData missing cols: {'No data exists for BANKNIFTY25JUNFUT'}
2025-06-25 18:04:01,118 [ERROR] true_data_utils: TrueData missing cols: {'No data exists for BANKNIFTY25JUNFUT'}
2025-06-25 18:05:00,746 [ERROR] true_data_utils: TrueData missing cols: {'No data exists for BANKNIFTY25JUNFUT'}
2025-06-25 18:06:01,366 [ERROR] true_data_utils: TrueData missing cols: {'No data exists for BANKNIFTY25JUNFUT'}
2025-06-25 18:07:01,085 [ERROR] true_data_utils: TrueData missing cols: {'No data exists for BANKNIFTY25JUNFUT'}
2025-06-25 18:08:00,746 [ERROR] true_data_utils: TrueData missing cols: {'No data exists for BANKNIFTY25JUNFUT'}
2025-06-25 18:09:01,408 [ERROR] true_data_utils: TrueData missing cols: {'No data exists for BANKNIFTY25JUNFUT'}
2025-06-25 18:10:01,080 [ERROR] true_data_utils: TrueData missing cols: {'No data exists for BANKNIFTY25JUNFUT'}
2025-06-25 18:11:00,794 [ERROR] true_data_utils: TrueData missing cols: {'No data exists for BANKNIFTY25JUNFUT'}
2025-06-25 18:12:01,448 [ERROR] true_data_utils: TrueData missing cols: {'No data exists for BANKNIFTY25JUNFUT'}
2025-06-25 18:13:01,104 [ERROR] true_data_utils: TrueData missing cols: {'No data exists for BANKNIFTY25JUNFUT'}
2025-06-25 18:14:00,775 [ERROR] true_data_utils: TrueData missing cols: {'No data exists for BANKNIFTY25JUNFUT'}
2025-06-25 18:15:01,336 [ERROR] true_data_utils: TrueData missing cols: {'No data exists for BANKNIFTY25JUNFUT'}
2025-06-25 18:16:00,991 [ERROR] true_data_utils: TrueData missing cols: {'No data exists for BANKNIFTY25JUNFUT'}
2025-06-25 18:17:00,540 [ERROR] true_data_utils: TrueData missing cols: {'No data exists for BANKNIFTY25JUNFUT'}
2025-06-25 18:18:01,103 [ERROR] true_data_utils: TrueData missing cols: {'No data exists for BANKNIFTY25JUNFUT'}
2025-06-25 18:19:00,736 [ERROR] true_data_utils: TrueData missing cols: {'No data exists for BANKNIFTY25JUNFUT'}
2025-06-25 18:20:01,396 [ERROR] true_data_utils: TrueData missing cols: {'No data exists for BANKNIFTY25JUNFUT'}
2025-06-25 18:21:01,052 [ERROR] true_data_utils: TrueData missing cols: {'No data exists for BANKNIFTY25JUNFUT'}
2025-06-25 18:22:00,765 [ERROR] true_data_utils: TrueData missing cols: {'No data exists for BANKNIFTY25JUNFUT'}
2025-06-25 18:23:01,364 [ERROR] true_data_utils: TrueData missing cols: {'No data exists for BANKNIFTY25JUNFUT'}
2025-06-25 18:24:01,202 [ERROR] true_data_utils: TrueData missing cols: {'No data exists for BANKNIFTY25JUNFUT'}
2025-06-25 18:25:00,765 [ERROR] true_data_utils: TrueData missing cols: {'No data exists for BANKNIFTY25JUNFUT'}
2025-06-25 18:26:01,404 [ERROR] true_data_utils: TrueData missing cols: {'No data exists for BANKNIFTY25JUNFUT'}
2025-06-25 18:27:00,958 [ERROR] true_data_utils: TrueData missing cols: {'No data exists for BANKNIFTY25JUNFUT'}
2025-06-25 18:28:00,740 [ERROR] true_data_utils: TrueData missing cols: {'No data exists for BANKNIFTY25JUNFUT'}
2025-06-25 18:29:01,422 [ERROR] true_data_utils: TrueData missing cols: {'No data exists for BANKNIFTY25JUNFUT'}
2025-06-25 18:30:01,108 [ERROR] true_data_utils: TrueData missing cols: {'No data exists for BANKNIFTY25JUNFUT'}
2025-06-25 18:31:00,701 [ERROR] true_data_utils: TrueData missing cols: {'No data exists for BANKNIFTY25JUNFUT'}
2025-06-25 18:32:01,443 [ERROR] true_data_utils: TrueData missing cols: {'No data exists for BANKNIFTY25JUNFUT'}
2025-06-25 18:33:01,143 [ERROR] true_data_utils: TrueData missing cols: {'No data exists for BANKNIFTY25JUNFUT'}
2025-06-25 18:34:00,742 [ERROR] true_data_utils: TrueData missing cols: {'No data exists for BANKNIFTY25JUNFUT'}
2025-06-25 18:35:01,369 [ERROR] true_data_utils: TrueData missing cols: {'No data exists for BANKNIFTY25JUNFUT'}
2025-06-25 18:36:01,039 [ERROR] true_data_utils: TrueData missing cols: {'No data exists for BANKNIFTY25JUNFUT'}
2025-06-25 18:37:00,634 [ERROR] true_data_utils: TrueData missing cols: {'No data exists for BANKNIFTY25JUNFUT'}
2025-06-25 18:38:01,284 [ERROR] true_data_utils: TrueData missing cols: {'No data exists for BANKNIFTY25JUNFUT'}
2025-06-25 18:39:00,951 [ERROR] true_data_utils: TrueData missing cols: {'No data exists for BANKNIFTY25JUNFUT'}
2025-06-25 18:40:00,687 [ERROR] true_data_utils: TrueData missing cols: {'No data exists for BANKNIFTY25JUNFUT'}
2025-06-25 18:41:01,366 [ERROR] true_data_utils: TrueData missing cols: {'No data exists for BANKNIFTY25JUNFUT'}
2025-06-25 18:42:01,053 [ERROR] true_data_utils: TrueData missing cols: {'No data exists for BANKNIFTY25JUNFUT'}
2025-06-25 18:43:00,673 [ERROR] true_data_utils: TrueData missing cols: {'No data exists for BANKNIFTY25JUNFUT'}
2025-06-25 18:44:01,471 [ERROR] true_data_utils: TrueData missing cols: {'No data exists for BANKNIFTY25JUNFUT'}
2025-06-25 18:45:01,141 [ERROR] true_data_utils: TrueData missing cols: {'No data exists for BANKNIFTY25JUNFUT'}
2025-06-25 18:46:00,812 [ERROR] true_data_utils: TrueData missing cols: {'No data exists for BANKNIFTY25JUNFUT'}
2025-06-25 18:47:01,499 [ERROR] true_data_utils: TrueData missing cols: {'No data exists for BANKNIFTY25JUNFUT'}
2025-06-25 18:48:01,236 [ERROR] true_data_utils: TrueData missing cols: {'No data exists for BANKNIFTY25JUNFUT'}
2025-06-25 18:49:00,919 [ERROR] true_data_utils: TrueData missing cols: {'No data exists for BANKNIFTY25JUNFUT'}
2025-06-25 18:50:00,594 [ERROR] true_data_utils: TrueData missing cols: {'No data exists for BANKNIFTY25JUNFUT'}
2025-06-25 18:51:01,241 [ERROR] true_data_utils: TrueData missing cols: {'No data exists for BANKNIFTY25JUNFUT'}
2025-06-25 18:52:00,939 [ERROR] true_data_utils: TrueData missing cols: {'No data exists for BANKNIFTY25JUNFUT'}
2025-06-25 18:53:00,602 [ERROR] true_data_utils: TrueData missing cols: {'No data exists for BANKNIFTY25JUNFUT'}
2025-06-25 18:54:01,299 [ERROR] true_data_utils: TrueData missing cols: {'No data exists for BANKNIFTY25JUNFUT'}
2025-06-25 18:55:00,950 [ERROR] true_data_utils: TrueData missing cols: {'No data exists for BANKNIFTY25JUNFUT'}
2025-06-25 18:56:00,640 [ERROR] true_data_utils: TrueData missing cols: {'No data exists for BANKNIFTY25JUNFUT'}
2025-06-25 18:57:01,230 [ERROR] true_data_utils: TrueData missing cols: {'No data exists for BANKNIFTY25JUNFUT'}
2025-06-25 18:58:01,067 [ERROR] true_data_utils: TrueData missing cols: {'No data exists for BANKNIFTY25JUNFUT'}
2025-06-25 18:59:00,716 [ERROR] true_data_utils: TrueData missing cols: {'No data exists for BANKNIFTY25JUNFUT'}
2025-06-25 19:00:01,940 [ERROR] true_data_utils: TrueData missing cols: {'No data exists for BANKNIFTY25JUNFUT'}
2025-06-25 19:01:00,546 [ERROR] true_data_utils: TrueData missing cols: {'No data exists for BANKNIFTY25JUNFUT'}
2025-06-25 19:02:01,223 [ERROR] true_data_utils: TrueData missing cols: {'No data exists for BANKNIFTY25JUNFUT'}
2025-06-25 19:03:00,979 [ERROR] true_data_utils: TrueData missing cols: {'No data exists for BANKNIFTY25JUNFUT'}
2025-06-25 19:04:00,648 [ERROR] true_data_utils: TrueData missing cols: {'No data exists for BANKNIFTY25JUNFUT'}
2025-06-25 19:05:01,299 [ERROR] true_data_utils: TrueData missing cols: {'No data exists for BANKNIFTY25JUNFUT'}
2025-06-25 19:06:01,082 [ERROR] true_data_utils: TrueData missing cols: {'No data exists for BANKNIFTY25JUNFUT'}
2025-06-25 19:07:00,750 [ERROR] true_data_utils: TrueData missing cols: {'No data exists for BANKNIFTY25JUNFUT'}
2025-06-25 19:08:01,508 [ERROR] true_data_utils: TrueData missing cols: {'No data exists for BANKNIFTY25JUNFUT'}
2025-06-25 19:09:01,155 [ERROR] true_data_utils: TrueData missing cols: {'No data exists for BANKNIFTY25JUNFUT'}
2025-06-25 19:10:00,839 [ERROR] true_data_utils: TrueData missing cols: {'No data exists for BANKNIFTY25JUNFUT'}
2025-06-25 19:11:01,488 [ERROR] true_data_utils: TrueData missing cols: {'No data exists for BANKNIFTY25JUNFUT'}
2025-06-25 19:12:01,218 [ERROR] true_data_utils: TrueData missing cols: {'No data exists for BANKNIFTY25JUNFUT'}
2025-06-25 19:13:00,792 [ERROR] true_data_utils: TrueData missing cols: {'No data exists for BANKNIFTY25JUNFUT'}
2025-06-25 19:14:01,497 [ERROR] true_data_utils: TrueData missing cols: {'No data exists for BANKNIFTY25JUNFUT'}
2025-06-25 19:15:01,142 [ERROR] true_data_utils: TrueData missing cols: {'No data exists for BANKNIFTY25JUNFUT'}
2025-06-25 19:16:00,900 [ERROR] true_data_utils: TrueData missing cols: {'No data exists for BANKNIFTY25JUNFUT'}
2025-06-25 19:17:00,626 [ERROR] true_data_utils: TrueData missing cols: {'No data exists for BANKNIFTY25JUNFUT'}
2025-06-25 19:18:01,328 [ERROR] true_data_utils: TrueData missing cols: {'No data exists for BANKNIFTY25JUNFUT'}
2025-06-25 19:19:00,934 [ERROR] true_data_utils: TrueData missing cols: {'No data exists for BANKNIFTY25JUNFUT'}
2025-06-25 19:20:00,759 [ERROR] true_data_utils: TrueData missing cols: {'No data exists for BANKNIFTY25JUNFUT'}
2025-06-25 19:21:01,585 [ERROR] true_data_utils: TrueData missing cols: {'No data exists for BANKNIFTY25JUNFUT'}
2025-06-25 19:22:01,291 [ERROR] true_data_utils: TrueData missing cols: {'No data exists for BANKNIFTY25JUNFUT'}
2025-06-25 19:23:00,911 [ERROR] true_data_utils: TrueData missing cols: {'No data exists for BANKNIFTY25JUNFUT'}
2025-06-25 19:24:00,600 [ERROR] true_data_utils: TrueData missing cols: {'No data exists for BANKNIFTY25JUNFUT'}
2025-06-25 19:25:01,264 [ERROR] true_data_utils: TrueData missing cols: {'No data exists for BANKNIFTY25JUNFUT'}
2025-06-25 19:26:01,132 [ERROR] true_data_utils: TrueData missing cols: {'No data exists for BANKNIFTY25JUNFUT'}
2025-06-25 19:27:00,795 [ERROR] true_data_utils: TrueData missing cols: {'No data exists for BANKNIFTY25JUNFUT'}
2025-06-25 19:28:01,498 [ERROR] true_data_utils: TrueData missing cols: {'No data exists for BANKNIFTY25JUNFUT'}
2025-06-25 19:29:01,195 [ERROR] true_data_utils: TrueData missing cols: {'No data exists for BANKNIFTY25JUNFUT'}
2025-06-25 19:30:00,908 [ERROR] true_data_utils: TrueData missing cols: {'No data exists for BANKNIFTY25JUNFUT'}
2025-06-25 19:31:00,521 [ERROR] true_data_utils: TrueData missing cols: {'No data exists for BANKNIFTY25JUNFUT'}
2025-06-25 19:32:01,229 [ERROR] true_data_utils: TrueData missing cols: {'No data exists for BANKNIFTY25JUNFUT'}
2025-06-25 19:33:00,856 [ERROR] true_data_utils: TrueData missing cols: {'No data exists for BANKNIFTY25JUNFUT'}
2025-06-25 19:34:01,462 [ERROR] true_data_utils: TrueData missing cols: {'No data exists for BANKNIFTY25JUNFUT'}
2025-06-25 19:35:01,170 [ERROR] true_data_utils: TrueData missing cols: {'No data exists for BANKNIFTY25JUNFUT'}
2025-06-25 19:36:00,854 [ERROR] true_data_utils: TrueData missing cols: {'No data exists for BANKNIFTY25JUNFUT'}
2025-06-25 19:37:01,557 [ERROR] true_data_utils: TrueData missing cols: {'No data exists for BANKNIFTY25JUNFUT'}
2025-06-25 19:38:01,202 [ERROR] true_data_utils: TrueData missing cols: {'No data exists for BANKNIFTY25JUNFUT'}
2025-06-25 19:39:00,864 [ERROR] true_data_utils: TrueData missing cols: {'No data exists for BANKNIFTY25JUNFUT'}
2025-06-25 19:40:01,646 [ERROR] true_data_utils: TrueData missing cols: {'No data exists for BANKNIFTY25JUNFUT'}
2025-06-25 19:41:01,285 [ERROR] true_data_utils: TrueData missing cols: {'No data exists for BANKNIFTY25JUNFUT'}
2025-06-25 19:42:00,939 [ERROR] true_data_utils: TrueData missing cols: {'No data exists for BANKNIFTY25JUNFUT'}
2025-06-25 19:43:00,639 [ERROR] true_data_utils: TrueData missing cols: {'No data exists for BANKNIFTY25JUNFUT'}
2025-06-25 19:44:01,327 [ERROR] true_data_utils: TrueData missing cols: {'No data exists for BANKNIFTY25JUNFUT'}
2025-06-25 19:45:00,999 [ERROR] true_data_utils: TrueData missing cols: {'No data exists for BANKNIFTY25JUNFUT'}
2025-06-25 19:46:00,766 [ERROR] true_data_utils: TrueData missing cols: {'No data exists for BANKNIFTY25JUNFUT'}
2025-06-25 19:47:01,474 [ERROR] true_data_utils: TrueData missing cols: {'No data exists for BANKNIFTY25JUNFUT'}
2025-06-25 19:48:01,145 [ERROR] true_data_utils: TrueData missing cols: {'No data exists for BANKNIFTY25JUNFUT'}
2025-06-25 19:49:00,820 [ERROR] true_data_utils: TrueData missing cols: {'No data exists for BANKNIFTY25JUNFUT'}
2025-06-25 19:50:01,497 [ERROR] true_data_utils: TrueData missing cols: {'No data exists for BANKNIFTY25JUNFUT'}
2025-06-25 19:51:01,093 [ERROR] true_data_utils: TrueData missing cols: {'No data exists for BANKNIFTY25JUNFUT'}
2025-06-25 19:52:00,763 [ERROR] true_data_utils: TrueData missing cols: {'No data exists for BANKNIFTY25JUNFUT'}
2025-06-25 19:53:01,405 [ERROR] true_data_utils: TrueData missing cols: {'No data exists for BANKNIFTY25JUNFUT'}
2025-06-25 19:54:01,097 [ERROR] true_data_utils: TrueData missing cols: {'No data exists for BANKNIFTY25JUNFUT'}
2025-06-25 19:55:00,748 [ERROR] true_data_utils: TrueData missing cols: {'No data exists for BANKNIFTY25JUNFUT'}
2025-06-25 19:56:01,547 [ERROR] true_data_utils: TrueData missing cols: {'No data exists for BANKNIFTY25JUNFUT'}
2025-06-25 19:57:01,131 [ERROR] true_data_utils: TrueData missing cols: {'No data exists for BANKNIFTY25JUNFUT'}
2025-06-25 19:58:00,821 [ERROR] true_data_utils: TrueData missing cols: {'No data exists for BANKNIFTY25JUNFUT'}
2025-06-25 19:59:01,502 [ERROR] true_data_utils: TrueData missing cols: {'No data exists for BANKNIFTY25JUNFUT'}
2025-06-25 20:00:01,340 [ERROR] true_data_utils: TrueData missing cols: {'No data exists for BANKNIFTY25JUNFUT'}
2025-06-25 20:01:00,983 [ERROR] true_data_utils: TrueData missing cols: {'No data exists for BANKNIFTY25JUNFUT'}
2025-06-25 20:02:00,677 [ERROR] true_data_utils: TrueData missing cols: {'No data exists for BANKNIFTY25JUNFUT'}
2025-06-25 20:03:01,296 [ERROR] true_data_utils: TrueData missing cols: {'No data exists for BANKNIFTY25JUNFUT'}
2025-06-25 20:04:00,991 [ERROR] true_data_utils: TrueData missing cols: {'No data exists for BANKNIFTY25JUNFUT'}
2025-06-25 20:05:00,668 [ERROR] true_data_utils: TrueData missing cols: {'No data exists for BANKNIFTY25JUNFUT'}
2025-06-25 20:06:01,355 [ERROR] true_data_utils: TrueData missing cols: {'No data exists for BANKNIFTY25JUNFUT'}
2025-06-25 20:07:00,998 [ERROR] true_data_utils: TrueData missing cols: {'No data exists for BANKNIFTY25JUNFUT'}
2025-06-25 20:08:00,664 [ERROR] true_data_utils: TrueData missing cols: {'No data exists for BANKNIFTY25JUNFUT'}
2025-06-25 20:09:01,307 [ERROR] true_data_utils: TrueData missing cols: {'No data exists for BANKNIFTY25JUNFUT'}
2025-06-25 20:10:00,942 [ERROR] true_data_utils: TrueData missing cols: {'No data exists for BANKNIFTY25JUNFUT'}
2025-06-25 20:11:00,711 [ERROR] true_data_utils: TrueData missing cols: {'No data exists for BANKNIFTY25JUNFUT'}
2025-06-25 20:12:01,401 [ERROR] true_data_utils: TrueData missing cols: {'No data exists for BANKNIFTY25JUNFUT'}
