2025-07-09 14:33:10,162 [ERROR] telegram: Telegram unauthorized (401) – check your TELEGRAM_TOKEN
2025-07-09 14:35:05,569 [ERROR] telegram: Telegram unauthorized (401) – check your TELEGRAM_TOKEN
2025-07-09 14:37:30,903 [ERROR] telegram: Telegram unauthorized (401) – check your TELEGRAM_TOKEN
2025-07-09 14:51:17,337 [ERROR] broker_utils: SELL order failed, response={'Success': None, 'Status': 500, 'Error': 'Resource not available'}
2025-07-09 16:03:15,133 [ERROR] true_data_utils: Attempt 1 fetch failed: HTTPSConnectionPool(host='auth.truedata.in', port=443): Max retries exceeded with url: /token (Caused by ConnectTimeoutError(<urllib3.connection.HTTPSConnection object at 0x10b0eb390>, 'Connection to auth.truedata.in timed out. (connect timeout=None)'))
Traceback (most recent call last):
  File "/Library/Frameworks/Python.framework/Versions/3.13/lib/python3.13/site-packages/urllib3/connection.py", line 174, in _new_conn
    conn = connection.create_connection(
        (self._dns_host, self.port), self.timeout, **extra_kw
    )
  File "/Library/Frameworks/Python.framework/Versions/3.13/lib/python3.13/site-packages/urllib3/util/connection.py", line 95, in create_connection
    raise err
  File "/Library/Frameworks/Python.framework/Versions/3.13/lib/python3.13/site-packages/urllib3/util/connection.py", line 85, in create_connection
    sock.connect(sa)
    ~~~~~~~~~~~~^^^^
TimeoutError: [Errno 60] Operation timed out

During handling of the above exception, another exception occurred:

Traceback (most recent call last):
  File "/Library/Frameworks/Python.framework/Versions/3.13/lib/python3.13/site-packages/urllib3/connectionpool.py", line 716, in urlopen
    httplib_response = self._make_request(
        conn,
    ...<5 lines>...
        chunked=chunked,
    )
  File "/Library/Frameworks/Python.framework/Versions/3.13/lib/python3.13/site-packages/urllib3/connectionpool.py", line 404, in _make_request
    self._validate_conn(conn)
    ~~~~~~~~~~~~~~~~~~~^^^^^^
  File "/Library/Frameworks/Python.framework/Versions/3.13/lib/python3.13/site-packages/urllib3/connectionpool.py", line 1061, in _validate_conn
    conn.connect()
    ~~~~~~~~~~~~^^
  File "/Library/Frameworks/Python.framework/Versions/3.13/lib/python3.13/site-packages/urllib3/connection.py", line 363, in connect
    self.sock = conn = self._new_conn()
                       ~~~~~~~~~~~~~~^^
  File "/Library/Frameworks/Python.framework/Versions/3.13/lib/python3.13/site-packages/urllib3/connection.py", line 179, in _new_conn
    raise ConnectTimeoutError(
    ...<3 lines>...
    )
urllib3.exceptions.ConnectTimeoutError: (<urllib3.connection.HTTPSConnection object at 0x10b0eb390>, 'Connection to auth.truedata.in timed out. (connect timeout=None)')

During handling of the above exception, another exception occurred:

Traceback (most recent call last):
  File "/Library/Frameworks/Python.framework/Versions/3.13/lib/python3.13/site-packages/requests/adapters.py", line 439, in send
    resp = conn.urlopen(
        method=request.method,
    ...<8 lines>...
        timeout=timeout
    )
  File "/Library/Frameworks/Python.framework/Versions/3.13/lib/python3.13/site-packages/urllib3/connectionpool.py", line 802, in urlopen
    retries = retries.increment(
        method, url, error=e, _pool=self, _stacktrace=sys.exc_info()[2]
    )
  File "/Library/Frameworks/Python.framework/Versions/3.13/lib/python3.13/site-packages/urllib3/util/retry.py", line 594, in increment
    raise MaxRetryError(_pool, url, error or ResponseError(cause))
urllib3.exceptions.MaxRetryError: HTTPSConnectionPool(host='auth.truedata.in', port=443): Max retries exceeded with url: /token (Caused by ConnectTimeoutError(<urllib3.connection.HTTPSConnection object at 0x10b0eb390>, 'Connection to auth.truedata.in timed out. (connect timeout=None)'))

During handling of the above exception, another exception occurred:

Traceback (most recent call last):
  File "/Users/aneeshviswanathan/Desktop/Db_Updated_om_babaji_om/true_data_utils.py", line 44, in fetch_latest_ohlcv
    token = get_token()
  File "/Users/aneeshviswanathan/Desktop/Db_Updated_om_babaji_om/true_data_utils.py", line 29, in get_token
    resp = requests.post(url, data=payload)
  File "/Library/Frameworks/Python.framework/Versions/3.13/lib/python3.13/site-packages/requests/api.py", line 119, in post
    return request('post', url, data=data, json=json, **kwargs)
  File "/Library/Frameworks/Python.framework/Versions/3.13/lib/python3.13/site-packages/requests/api.py", line 61, in request
    return session.request(method=method, url=url, **kwargs)
           ~~~~~~~~~~~~~~~^^^^^^^^^^^^^^^^^^^^^^^^^^^^^^^^^^
  File "/Library/Frameworks/Python.framework/Versions/3.13/lib/python3.13/site-packages/requests/sessions.py", line 542, in request
    resp = self.send(prep, **send_kwargs)
  File "/Library/Frameworks/Python.framework/Versions/3.13/lib/python3.13/site-packages/requests/sessions.py", line 655, in send
    r = adapter.send(request, **kwargs)
  File "/Library/Frameworks/Python.framework/Versions/3.13/lib/python3.13/site-packages/requests/adapters.py", line 504, in send
    raise ConnectTimeout(e, request=request)
requests.exceptions.ConnectTimeout: HTTPSConnectionPool(host='auth.truedata.in', port=443): Max retries exceeded with url: /token (Caused by ConnectTimeoutError(<urllib3.connection.HTTPSConnection object at 0x10b0eb390>, 'Connection to auth.truedata.in timed out. (connect timeout=None)'))
2025-07-09 18:00:20,084 [ERROR] true_data_utils: TrueData missing cols: {'No data exists for BANKNIFTY25JULFUT'}
