2025-06-26 09:08:22,658 [ERROR] true_data_utils: TrueData missing cols: {'No data exists for BANKNIFTY25JULFUT'}
2025-06-26 09:09:01,379 [ERROR] true_data_utils: TrueData missing cols: {'No data exists for BANKNIFTY25JULFUT'}
2025-06-26 09:10:01,167 [ERROR] true_data_utils: TrueData missing cols: {'No data exists for BANKNIFTY25JULFUT'}
2025-06-26 09:11:00,860 [ERROR] true_data_utils: TrueData missing cols: {'No data exists for BANKNIFTY25JULFUT'}
2025-06-26 09:12:00,597 [ERROR] true_data_utils: TrueData missing cols: {'No data exists for BANKNIFTY25JULFUT'}
2025-06-26 09:13:01,285 [ERROR] true_data_utils: TrueData missing cols: {'No data exists for BANKNIFTY25JULFUT'}
2025-06-26 09:14:01,019 [ERROR] true_data_utils: TrueData missing cols: {'No data exists for BANKNIFTY25JULFUT'}
2025-06-26 09:15:00,734 [ERROR] true_data_utils: TrueData missing cols: {'No data exists for BANKNIFTY25JULFUT'}
2025-06-26 11:00:15,566 [ERROR] true_data_utils: Attempt 1 fetch failed: HTTPSConnectionPool(host='auth.truedata.in', port=443): Max retries exceeded with url: /token (Caused by ConnectTimeoutError(<urllib3.connection.HTTPSConnection object at 0x10718e990>, 'Connection to auth.truedata.in timed out. (connect timeout=None)'))
Traceback (most recent call last):
  File "/Library/Frameworks/Python.framework/Versions/3.13/lib/python3.13/site-packages/urllib3/connection.py", line 174, in _new_conn
    conn = connection.create_connection(
        (self._dns_host, self.port), self.timeout, **extra_kw
    )
  File "/Library/Frameworks/Python.framework/Versions/3.13/lib/python3.13/site-packages/urllib3/util/connection.py", line 95, in create_connection
    raise err
  File "/Library/Frameworks/Python.framework/Versions/3.13/lib/python3.13/site-packages/urllib3/util/connection.py", line 85, in create_connection
    sock.connect(sa)
    ~~~~~~~~~~~~^^^^
TimeoutError: [Errno 60] Operation timed out

During handling of the above exception, another exception occurred:

Traceback (most recent call last):
  File "/Library/Frameworks/Python.framework/Versions/3.13/lib/python3.13/site-packages/urllib3/connectionpool.py", line 716, in urlopen
    httplib_response = self._make_request(
        conn,
    ...<5 lines>...
        chunked=chunked,
    )
  File "/Library/Frameworks/Python.framework/Versions/3.13/lib/python3.13/site-packages/urllib3/connectionpool.py", line 404, in _make_request
    self._validate_conn(conn)
    ~~~~~~~~~~~~~~~~~~~^^^^^^
  File "/Library/Frameworks/Python.framework/Versions/3.13/lib/python3.13/site-packages/urllib3/connectionpool.py", line 1061, in _validate_conn
    conn.connect()
    ~~~~~~~~~~~~^^
  File "/Library/Frameworks/Python.framework/Versions/3.13/lib/python3.13/site-packages/urllib3/connection.py", line 363, in connect
    self.sock = conn = self._new_conn()
                       ~~~~~~~~~~~~~~^^
  File "/Library/Frameworks/Python.framework/Versions/3.13/lib/python3.13/site-packages/urllib3/connection.py", line 179, in _new_conn
    raise ConnectTimeoutError(
    ...<3 lines>...
    )
urllib3.exceptions.ConnectTimeoutError: (<urllib3.connection.HTTPSConnection object at 0x10718e990>, 'Connection to auth.truedata.in timed out. (connect timeout=None)')

During handling of the above exception, another exception occurred:

Traceback (most recent call last):
  File "/Library/Frameworks/Python.framework/Versions/3.13/lib/python3.13/site-packages/requests/adapters.py", line 439, in send
    resp = conn.urlopen(
        method=request.method,
    ...<8 lines>...
        timeout=timeout
    )
  File "/Library/Frameworks/Python.framework/Versions/3.13/lib/python3.13/site-packages/urllib3/connectionpool.py", line 802, in urlopen
    retries = retries.increment(
        method, url, error=e, _pool=self, _stacktrace=sys.exc_info()[2]
    )
  File "/Library/Frameworks/Python.framework/Versions/3.13/lib/python3.13/site-packages/urllib3/util/retry.py", line 594, in increment
    raise MaxRetryError(_pool, url, error or ResponseError(cause))
urllib3.exceptions.MaxRetryError: HTTPSConnectionPool(host='auth.truedata.in', port=443): Max retries exceeded with url: /token (Caused by ConnectTimeoutError(<urllib3.connection.HTTPSConnection object at 0x10718e990>, 'Connection to auth.truedata.in timed out. (connect timeout=None)'))

During handling of the above exception, another exception occurred:

Traceback (most recent call last):
  File "/Users/aneeshviswanathan/Desktop/Updated_om_babaji_om /true_data_utils.py", line 44, in fetch_latest_ohlcv
    token = get_token()
  File "/Users/aneeshviswanathan/Desktop/Updated_om_babaji_om /true_data_utils.py", line 29, in get_token
    resp = requests.post(url, data=payload)
  File "/Library/Frameworks/Python.framework/Versions/3.13/lib/python3.13/site-packages/requests/api.py", line 119, in post
    return request('post', url, data=data, json=json, **kwargs)
  File "/Library/Frameworks/Python.framework/Versions/3.13/lib/python3.13/site-packages/requests/api.py", line 61, in request
    return session.request(method=method, url=url, **kwargs)
           ~~~~~~~~~~~~~~~^^^^^^^^^^^^^^^^^^^^^^^^^^^^^^^^^^
  File "/Library/Frameworks/Python.framework/Versions/3.13/lib/python3.13/site-packages/requests/sessions.py", line 542, in request
    resp = self.send(prep, **send_kwargs)
  File "/Library/Frameworks/Python.framework/Versions/3.13/lib/python3.13/site-packages/requests/sessions.py", line 655, in send
    r = adapter.send(request, **kwargs)
  File "/Library/Frameworks/Python.framework/Versions/3.13/lib/python3.13/site-packages/requests/adapters.py", line 504, in send
    raise ConnectTimeout(e, request=request)
requests.exceptions.ConnectTimeout: HTTPSConnectionPool(host='auth.truedata.in', port=443): Max retries exceeded with url: /token (Caused by ConnectTimeoutError(<urllib3.connection.HTTPSConnection object at 0x10718e990>, 'Connection to auth.truedata.in timed out. (connect timeout=None)'))
2025-06-26 11:00:16,000 [ERROR] atm_strike: Error fetching BANKNIFTY spot price
Traceback (most recent call last):
  File "/Library/Frameworks/Python.framework/Versions/3.13/lib/python3.13/site-packages/urllib3/connection.py", line 174, in _new_conn
    conn = connection.create_connection(
        (self._dns_host, self.port), self.timeout, **extra_kw
    )
  File "/Library/Frameworks/Python.framework/Versions/3.13/lib/python3.13/site-packages/urllib3/util/connection.py", line 95, in create_connection
    raise err
  File "/Library/Frameworks/Python.framework/Versions/3.13/lib/python3.13/site-packages/urllib3/util/connection.py", line 85, in create_connection
    sock.connect(sa)
    ~~~~~~~~~~~~^^^^
TimeoutError: [Errno 60] Operation timed out

During handling of the above exception, another exception occurred:

Traceback (most recent call last):
  File "/Library/Frameworks/Python.framework/Versions/3.13/lib/python3.13/site-packages/urllib3/connectionpool.py", line 716, in urlopen
    httplib_response = self._make_request(
        conn,
    ...<5 lines>...
        chunked=chunked,
    )
  File "/Library/Frameworks/Python.framework/Versions/3.13/lib/python3.13/site-packages/urllib3/connectionpool.py", line 404, in _make_request
    self._validate_conn(conn)
    ~~~~~~~~~~~~~~~~~~~^^^^^^
  File "/Library/Frameworks/Python.framework/Versions/3.13/lib/python3.13/site-packages/urllib3/connectionpool.py", line 1061, in _validate_conn
    conn.connect()
    ~~~~~~~~~~~~^^
  File "/Library/Frameworks/Python.framework/Versions/3.13/lib/python3.13/site-packages/urllib3/connection.py", line 363, in connect
    self.sock = conn = self._new_conn()
                       ~~~~~~~~~~~~~~^^
  File "/Library/Frameworks/Python.framework/Versions/3.13/lib/python3.13/site-packages/urllib3/connection.py", line 179, in _new_conn
    raise ConnectTimeoutError(
    ...<3 lines>...
    )
urllib3.exceptions.ConnectTimeoutError: (<urllib3.connection.HTTPSConnection object at 0x146bd0050>, 'Connection to api.icicidirect.com timed out. (connect timeout=None)')

During handling of the above exception, another exception occurred:

Traceback (most recent call last):
  File "/Library/Frameworks/Python.framework/Versions/3.13/lib/python3.13/site-packages/requests/adapters.py", line 439, in send
    resp = conn.urlopen(
        method=request.method,
    ...<8 lines>...
        timeout=timeout
    )
  File "/Library/Frameworks/Python.framework/Versions/3.13/lib/python3.13/site-packages/urllib3/connectionpool.py", line 802, in urlopen
    retries = retries.increment(
        method, url, error=e, _pool=self, _stacktrace=sys.exc_info()[2]
    )
  File "/Library/Frameworks/Python.framework/Versions/3.13/lib/python3.13/site-packages/urllib3/util/retry.py", line 594, in increment
    raise MaxRetryError(_pool, url, error or ResponseError(cause))
urllib3.exceptions.MaxRetryError: HTTPSConnectionPool(host='api.icicidirect.com', port=443): Max retries exceeded with url: /breezeapi/api/v1/quotes (Caused by ConnectTimeoutError(<urllib3.connection.HTTPSConnection object at 0x146bd0050>, 'Connection to api.icicidirect.com timed out. (connect timeout=None)'))

During handling of the above exception, another exception occurred:

Traceback (most recent call last):
  File "/Library/Frameworks/Python.framework/Versions/3.13/lib/python3.13/site-packages/breeze_connect/breeze_connect.py", line 1120, in make_request
    res = requests.get(url=url, data=body, headers=headers)
  File "/Library/Frameworks/Python.framework/Versions/3.13/lib/python3.13/site-packages/requests/api.py", line 76, in get
    return request('get', url, params=params, **kwargs)
  File "/Library/Frameworks/Python.framework/Versions/3.13/lib/python3.13/site-packages/requests/api.py", line 61, in request
    return session.request(method=method, url=url, **kwargs)
           ~~~~~~~~~~~~~~~^^^^^^^^^^^^^^^^^^^^^^^^^^^^^^^^^^
  File "/Library/Frameworks/Python.framework/Versions/3.13/lib/python3.13/site-packages/requests/sessions.py", line 542, in request
    resp = self.send(prep, **send_kwargs)
  File "/Library/Frameworks/Python.framework/Versions/3.13/lib/python3.13/site-packages/requests/sessions.py", line 655, in send
    r = adapter.send(request, **kwargs)
  File "/Library/Frameworks/Python.framework/Versions/3.13/lib/python3.13/site-packages/requests/adapters.py", line 504, in send
    raise ConnectTimeout(e, request=request)
requests.exceptions.ConnectTimeout: HTTPSConnectionPool(host='api.icicidirect.com', port=443): Max retries exceeded with url: /breezeapi/api/v1/quotes (Caused by ConnectTimeoutError(<urllib3.connection.HTTPSConnection object at 0x146bd0050>, 'Connection to api.icicidirect.com timed out. (connect timeout=None)'))

During handling of the above exception, another exception occurred:

Traceback (most recent call last):
  File "/Library/Frameworks/Python.framework/Versions/3.13/lib/python3.13/site-packages/breeze_connect/breeze_connect.py", line 1847, in get_quotes
    response = self.make_request(req_type.GET, api_endpoint.QUOTE.value, body, headers)
  File "/Library/Frameworks/Python.framework/Versions/3.13/lib/python3.13/site-packages/breeze_connect/breeze_connect.py", line 1132, in make_request
    self.error_exception(except_message.API_REQUEST_EXCEPTION.value.format(method,url),e)
    ~~~~~~~~~~~~~~~~~~~~^^^^^^^^^^^^^^^^^^^^^^^^^^^^^^^^^^^^^^^^^^^^^^^^^^^^^^^^^^^^^^^^^
  File "/Library/Frameworks/Python.framework/Versions/3.13/lib/python3.13/site-packages/breeze_connect/breeze_connect.py", line 1090, in error_exception
    raise Exception(message).with_traceback(error.__traceback__)
  File "/Library/Frameworks/Python.framework/Versions/3.13/lib/python3.13/site-packages/breeze_connect/breeze_connect.py", line 1120, in make_request
    res = requests.get(url=url, data=body, headers=headers)
  File "/Library/Frameworks/Python.framework/Versions/3.13/lib/python3.13/site-packages/requests/api.py", line 76, in get
    return request('get', url, params=params, **kwargs)
  File "/Library/Frameworks/Python.framework/Versions/3.13/lib/python3.13/site-packages/requests/api.py", line 61, in request
    return session.request(method=method, url=url, **kwargs)
           ~~~~~~~~~~~~~~~^^^^^^^^^^^^^^^^^^^^^^^^^^^^^^^^^^
  File "/Library/Frameworks/Python.framework/Versions/3.13/lib/python3.13/site-packages/requests/sessions.py", line 542, in request
    resp = self.send(prep, **send_kwargs)
  File "/Library/Frameworks/Python.framework/Versions/3.13/lib/python3.13/site-packages/requests/sessions.py", line 655, in send
    r = adapter.send(request, **kwargs)
  File "/Library/Frameworks/Python.framework/Versions/3.13/lib/python3.13/site-packages/requests/adapters.py", line 504, in send
    raise ConnectTimeout(e, request=request)
Exception: Error while trying to make request GET https://api.icicidirect.com/breezeapi/api/v1/quotes() Error

During handling of the above exception, another exception occurred:

Traceback (most recent call last):
  File "/Library/Frameworks/Python.framework/Versions/3.13/lib/python3.13/site-packages/breeze_connect/breeze_connect.py", line 1020, in get_quotes
    return self.api_handler.get_quotes(stock_code, exchange_code, expiry_date, product_type, right, strike_price)
           ~~~~~~~~~~~~~~~~~~~~~~~~~~~^^^^^^^^^^^^^^^^^^^^^^^^^^^^^^^^^^^^^^^^^^^^^^^^^^^^^^^^^^^^^^^^^^^^^^^^^^^
  File "/Library/Frameworks/Python.framework/Versions/3.13/lib/python3.13/site-packages/breeze_connect/breeze_connect.py", line 1851, in get_quotes
    self.error_exception(self.get_quotes.__name__,e)
    ~~~~~~~~~~~~~~~~~~~~^^^^^^^^^^^^^^^^^^^^^^^^^^^^
  File "/Library/Frameworks/Python.framework/Versions/3.13/lib/python3.13/site-packages/breeze_connect/breeze_connect.py", line 1090, in error_exception
    raise Exception(message).with_traceback(error.__traceback__)
  File "/Library/Frameworks/Python.framework/Versions/3.13/lib/python3.13/site-packages/breeze_connect/breeze_connect.py", line 1847, in get_quotes
    response = self.make_request(req_type.GET, api_endpoint.QUOTE.value, body, headers)
  File "/Library/Frameworks/Python.framework/Versions/3.13/lib/python3.13/site-packages/breeze_connect/breeze_connect.py", line 1132, in make_request
    self.error_exception(except_message.API_REQUEST_EXCEPTION.value.format(method,url),e)
    ~~~~~~~~~~~~~~~~~~~~^^^^^^^^^^^^^^^^^^^^^^^^^^^^^^^^^^^^^^^^^^^^^^^^^^^^^^^^^^^^^^^^^
  File "/Library/Frameworks/Python.framework/Versions/3.13/lib/python3.13/site-packages/breeze_connect/breeze_connect.py", line 1090, in error_exception
    raise Exception(message).with_traceback(error.__traceback__)
  File "/Library/Frameworks/Python.framework/Versions/3.13/lib/python3.13/site-packages/breeze_connect/breeze_connect.py", line 1120, in make_request
    res = requests.get(url=url, data=body, headers=headers)
  File "/Library/Frameworks/Python.framework/Versions/3.13/lib/python3.13/site-packages/requests/api.py", line 76, in get
    return request('get', url, params=params, **kwargs)
  File "/Library/Frameworks/Python.framework/Versions/3.13/lib/python3.13/site-packages/requests/api.py", line 61, in request
    return session.request(method=method, url=url, **kwargs)
           ~~~~~~~~~~~~~~~^^^^^^^^^^^^^^^^^^^^^^^^^^^^^^^^^^
  File "/Library/Frameworks/Python.framework/Versions/3.13/lib/python3.13/site-packages/requests/sessions.py", line 542, in request
    resp = self.send(prep, **send_kwargs)
  File "/Library/Frameworks/Python.framework/Versions/3.13/lib/python3.13/site-packages/requests/sessions.py", line 655, in send
    r = adapter.send(request, **kwargs)
  File "/Library/Frameworks/Python.framework/Versions/3.13/lib/python3.13/site-packages/requests/adapters.py", line 504, in send
    raise ConnectTimeout(e, request=request)
Exception: get_quotes() Error

During handling of the above exception, another exception occurred:

Traceback (most recent call last):
  File "/Users/aneeshviswanathan/Desktop/Updated_om_babaji_om /atm_strike.py", line 19, in get_banknifty_spot_index_price
    resp = breeze.get_quotes(
        stock_code=SYMBOL_PREFIX,
        exchange_code="NSE",
        product_type="cash"
    )
  File "/Library/Frameworks/Python.framework/Versions/3.13/lib/python3.13/site-packages/breeze_connect/breeze_connect.py", line 1022, in get_quotes
    self.error_exception(self.get_quotes.__name__,e)
    ^^^^^^^^^^^^^^^^^^^^
AttributeError: 'BreezeConnect' object has no attribute 'error_exception'
2025-06-26 14:27:02,187 [ERROR] broker_utils: BUY order failed, response={'Success': None, 'Status': 500, 'Error': 'Please enter lots in multiple of defined contract lot.: '}
